Workbook
Name Part_s: [1]Sheet2!$G$8:$G$15
Name Part_s: Sheet2!$G$8:$G$15

Sheet 설비 Master Sheet
I1: warranty out | J1: 총 설비수량 | K1: =COUNTA(O8:O10007) -> 299 | L1: =K1=K2+K3 -> TRUE | N1: 월별 유상설비 수량 | O1: 1 | P1: 2 | Q1: 3 | R1: 4 | S1: 5 | T1: 6
C2: 모델명 및 설비 TYPE 기존 기입 데이터 참고하여 기입 | H2: 반입/셋업없음 | I2: =COUNTIFS(L8:L10007,"",M8:M10007,"",O8:O10007,"OUT") -> 116 | J2: Warrany OUT | K2: =COUNTIF(O:O,"OUT") -> 265 | L2: 팀 인원 | M2: 인당 관리대수 | O2: =COUNTIFS($M$8:$M$10007,"<>",$M$8:$M$10007,"<"&DATE(2025,O1,1)-365)+$I$2 -> 238 | P2: =COUNTIFS($M$8:$M$10007,"<>",$M$8:$M$10007,"<"&DATE(2025,P1,1)-365)+$I$2 -> 240 | Q2: =COUNTIFS($M$8:$M$10007,"<>",$M$8:$M$10007,"<"&DATE(2025,Q1,1)-365)+$I$2 -> 241 | R2: =COUNTIFS($M$8:$M$10007,"<>",$M$8:$M$10007,"<"&DATE(2025,R1,1)-365)+$I$2 -> 245 | S2: =COUNTIFS($M$8:$M$10007,"<>",$M$8:$M$10007,"<"&DATE(2025,S1,1)-365)+$I$2 -> 250 | T2: =COUNTIFS($M$8:$M$10007,"<>",$M$8:$M$10007,"<"&DATE(2025,T1,1)-365)+$I$2 -> 250
J3: Warrany IN | K3: =COUNTIF(O:O,"IN") -> 34 | L3: 5 | M3: =K1/L3 -> 59.8 | O3: 7 | P3: 8 | Q3: 9 | R3: 10 | S3: 11 | T3: 12
O4: =COUNTIFS($M$8:$M$10007,"<>",$M$8:$M$10007,"<"&DATE(2025,O3,1)-365)+$I$2 -> 254 | P4: =COUNTIFS($M$8:$M$10007,"<>",$M$8:$M$10007,"<"&DATE(2025,P3,1)-365)+$I$2 -> 255 | Q4: =COUNTIFS($M$8:$M$10007,"<>",$M$8:$M$10007,"<"&DATE(2025,Q3,1)-365)+$I$2 -> 258 | R4: =COUNTIFS($M$8:$M$10007,"<>",$M$8:$M$10007,"<"&DATE(2025,R3,1)-365)+$I$2 -> 259 | S4: =COUNTIFS($M$8:$M$10007,"<>",$M$8:$M$10007,"<"&DATE(2025,S3,1)-365)+$I$2 -> 260 | T4: =COUNTIFS($M$8:$M$10007,"<>",$M$8:$M$10007,"<"&DATE(2025,T3,1)-365)+$I$2 -> 261
B5: ■ 종합사이트 Master Sheet
B6: No | C6: 상호 | D6: 지역 | E6: 상세위치 | F6: 공정 | G6: 사용가스 | H6: 호기 | I6: MODEL | J6: S/N | K6: TYPE | L6: 반입일 | M6: SET UP | N6: 이설 Set-Up일 | O6: WARRENTY | P6: Inlet 사용port | Q6: 외부 Tank 사용 여부 | R6: Blower | S6: Heater 종류 | T6: 방문이력 | U6: 비고/특이사항
B8: 2 | C8: AP System | D8: 오산 | I8: 507BWA | J8: M002442 | K8: HEAT-WET | O8: =IF(AND(M8="",L8=""),"OUT",IF(M8="","IN",IF(TODAY()>M8+365,"OUT","IN"))) -> OUT | T8: X
B9: 3 | C9: BJ Power | D9: 대전 | I9: 507BW | K9: HEAT-WET | O9: =IF(AND(M9="",L9=""),"OUT",IF(M9="","IN",IF(TODAY()>M9+365,"OUT","IN"))) -> OUT | T9: X
B10: 4 | C10: JNK | D10: 마도 | I10: 601PW | J10: M001842 | K10: PLASMA | O10: =IF(AND(M10="",L10=""),"OUT",IF(M10="","IN",IF(TODAY()>M10+365,"OUT","IN"))) -> OUT | T10: X
I11: 507BWA | K11: HEAT-WET | O11: =IF(AND(M11="",L11=""),"OUT",IF(M11="","IN",IF(TODAY()>M11+365,"OUT","IN"))) -> OUT | T11: X
B12: 5 | C12: Kanc | D12: 수원 | H12: EP-1172 | I12: 1207BW | J12: M001021 | K12: HEAT-WET | O12: =IF(AND(M12="",L12=""),"OUT",IF(M12="","IN",IF(TODAY()>M12+365,"OUT","IN"))) -> OUT | T12: X
D13: 수원 | I13: MAT501BW | J13: 970516-GS-0116 | K13: HEAT-WET | O13: =IF(AND(M13="",L13=""),"OUT",IF(M13="","IN",IF(TODAY()>M13+365,"OUT","IN"))) -> OUT | T13: X
B14: 6 | C14: KEC | D14: 구미 | I14: 507BWA | J14: M001762 | K14: HEAT-WET | O14: =IF(AND(M14="",L14=""),"OUT",IF(M14="","IN",IF(TODAY()>M14+365,"OUT","IN"))) -> OUT | P14: 2 | Q14: X | R14: O | S14: 칸탈 | T14: O
I15: 507BWA | J15: M001985 | K15: HEAT-WET | O15: =IF(AND(M15="",L15=""),"OUT",IF(M15="","IN",IF(TODAY()>M15+365,"OUT","IN"))) -> OUT | P15: 3 | Q15: X | R15: O | S15: 칸탈 | T15: O
I16: 507BW | J16: 20050331-KE-1158 | K16: HEAT-WET | O16: =IF(AND(M16="",L16=""),"OUT",IF(M16="","IN",IF(TODAY()>M16+365,"OUT","IN"))) -> OUT | Q16: X | R16: O | S16: 칸탈 | T16: O
F17: HTO | I17: 507BW | J17: 20050331-KE-1159 | K17: HEAT-WET | O17: =IF(AND(M17="",L17=""),"OUT",IF(M17="","IN",IF(TODAY()>M17+365,"OUT","IN"))) -> OUT | P17: 1 | Q17: X | R17: O | S17: 칸탈 | T17: O
F18: CVD | I18: 507BW | J18: 20050331-KE-1160 | K18: HEAT-WET | O18: =IF(AND(M18="",L18=""),"OUT",IF(M18="","IN",IF(TODAY()>M18+365,"OUT","IN"))) -> OUT | Q18: X | R18: O | S18: 칸탈 | T18: O
F19: POLY | I19: 507BW | J19: 20050331-KE-1161 | K19: HEAT-WET | O19: =IF(AND(M19="",L19=""),"OUT",IF(M19="","IN",IF(TODAY()>M19+365,"OUT","IN"))) -> OUT | Q19: X | R19: O | S19: 칸탈 | T19: O
F20: CVD | I20: 507BW | J20: 20050331-KE-1162 | K20: HEAT-WET | O20: =IF(AND(M20="",L20=""),"OUT",IF(M20="","IN",IF(TODAY()>M20+365,"OUT","IN"))) -> OUT | Q20: X | R20: O | S20: 칸탈 | T20: O
F21: ETCH | I21: 507BW | J21: 20050331-KE-1164 | K21: HEAT-WET | O21: =IF(AND(M21="",L21=""),"OUT",IF(M21="","IN",IF(TODAY()>M21+365,"OUT","IN"))) -> OUT | Q21: X | R21: O | S21: 칸탈 | T21: O
F22: GAS ROOM | I22: 507BW | J22: 20050331-KE-1165 | K22: HEAT-WET | O22: =IF(AND(M22="",L22=""),"OUT",IF(M22="","IN",IF(TODAY()>M22+365,"OUT","IN"))) -> OUT | Q22: X | R22: O | S22: 칸탈 | T22: O | U22: 가스룸 설비 (2025.05.12 추가)
F23: CVD | I23: 1207BW | J23: 20051215-KE-1307 | K23: HEAT-WET | O23: =IF(AND(M23="",L23=""),"OUT",IF(M23="","IN",IF(TODAY()>M23+365,"OUT","IN"))) -> OUT | Q23: X | R23: O | S23: 칸탈 | T23: O
F24: CVD | I24: 507BWS | J24: M006188 | K24: HEAT-WET | L24: 44624 | M24: 44642 | O24: =IF(AND(M24="",L24=""),"OUT",IF(M24="","IN",IF(TODAY()>M24+365,"OUT","IN"))) -> OUT | P24: 2 | Q24: X | R24: O | S24: 칸탈 | T24: O
F25: TEOS | I25: 507BWS | J25: M006499 | K25: HEAT-WET | L25: 44845 | M25: 44853 | O25: =IF(AND(M25="",L25=""),"OUT",IF(M25="","IN",IF(TODAY()>M25+365,"OUT","IN"))) -> OUT | P25: 1 | Q25: X | R25: O | S25: 칸탈 | T25: O
B26: 8 | C26: LG전자기술 연구소 | D26: 서울 우면동 | I26: 1207BWA | J26: M001919 | K26: HEAT-WET | M26: 43069 | O26: =IF(AND(M26="",L26=""),"OUT",IF(M26="","IN",IF(TODAY()>M26+365,"OUT","IN"))) -> OUT | P26: - | Q26: - | R26: - | S26: - | T26: O
I27: 507BWS | J27: M002615 | K27: HEAT-WET | M27: 43069 | O27: =IF(AND(M27="",L27=""),"OUT",IF(M27="","IN",IF(TODAY()>M27+365,"OUT","IN"))) -> OUT | P27: - | Q27: - | R27: - | S27: - | T27: O | U27: 2025년 7월 한국 공학대학에 중고로 판매
B28: 9 | C28: LG 화학 기술연구원 | D28: 대전 | I28: 507BWA | J28: M002581 | K28: HEAT-WET | O28: =IF(AND(M28="",L28=""),"OUT",IF(M28="","IN",IF(TODAY()>M28+365,"OUT","IN"))) -> OUT | T28: X
I29: 1501HW | J29: M006175 | K29: HEAT-WET | L29: 44544 | M29: 44573 | O29: =IF(AND(M29="",L29=""),"OUT",IF(M29="","IN",IF(TODAY()>M29+365,"OUT","IN"))) -> OUT | P29: 2 | Q29: X | R29: X | S29: 칸탈 | T29: O
B30: 10 | C30: SK 머티리얼즈 | D30: 영주 | I30: 1207BW | J30: M002097 | K30: HEAT-WET | O30: =IF(AND(M30="",L30=""),"OUT",IF(M30="","IN",IF(TODAY()>M30+365,"OUT","IN"))) -> OUT | T30: X
I31: MAT501 | K31: HEAT-WET | O31: =IF(AND(M31="",L31=""),"OUT",IF(M31="","IN",IF(TODAY()>M31+365,"OUT","IN"))) -> OUT | T31: X
D32: 군산 | I32: 1207BW | J32: M002089 | K32: HEAT-WET | O32: =IF(AND(M32="",L32=""),"OUT",IF(M32="","IN",IF(TODAY()>M32+365,"OUT","IN"))) -> OUT | T32: X
B33: 11 | C33: PPI | D33: 광주 | I33: 507BWS | J33: M002260 | K33: HEAT-WET | O33: =IF(AND(M33="",L33=""),"OUT",IF(M33="","IN",IF(TODAY()>M33+365,"OUT","IN"))) -> OUT | T33: X
I34: MAT501BW | J34: 20030623-PP-595 | K34: HEAT-WET | O34: =IF(AND(M34="",L34=""),"OUT",IF(M34="","IN",IF(TODAY()>M34+365,"OUT","IN"))) -> OUT | T34: X
B35: 12 | C35: SFA | D35: 기흥 | I35: MI2500 | J35: M001817 | K35: HEAT-WET | O35: =IF(AND(M35="",L35=""),"OUT",IF(M35="","IN",IF(TODAY()>M35+365,"OUT","IN"))) -> OUT | T35: X
B36: 13 | C36: SK 이노베이션 | I36: FCTO2000W | J36: M002594 | K36: FCTO | O36: =IF(AND(M36="",L36=""),"OUT",IF(M36="","IN",IF(TODAY()>M36+365,"OUT","IN"))) -> OUT | T36: X
B37: 14 | C37: SMP 삼성정밀화학 | D37: 울산 | I37: 1207BWA | J37: M002613 | K37: HEAT-WET | O37: =IF(AND(M37="",L37=""),"OUT",IF(M37="","IN",IF(TODAY()>M37+365,"OUT","IN"))) -> OUT | T37: X
B38: 15 | C38: STX 솔라 | D38: 구미 | I38: 507BWA | K38: HEAT-WET | O38: =IF(AND(M38="",L38=""),"OUT",IF(M38="","IN",IF(TODAY()>M38+365,"OUT","IN"))) -> OUT | T38: X
I39: 403W | J39: M002507 | K39: WET | O39: =IF(AND(M39="",L39=""),"OUT",IF(M39="","IN",IF(TODAY()>M39+365,"OUT","IN"))) -> OUT | T39: X
B40: 16 | C40: 가천대학교 | E40: 반도체대학 1층 크린룸 | F40: ALD | G40: TMA, CL2 | I40: 507BWS | J40: M007617 | K40: HEAT-WET | L40: 45784 | M40: 45818 | O40: =IF(AND(M40="",L40=""),"OUT",IF(M40="","IN",IF(TODAY()>M40+365,"OUT","IN"))) -> IN | P40: 1 | Q40: X | R40: X | S40: 칸탈 | T40: O
B41: 17 | C41: 경북과학기술원 | D41: 대구 | I41: 1207BWA | J41: M002441 | K41: HEAT-WET | O41: =IF(AND(M41="",L41=""),"OUT",IF(M41="","IN",IF(TODAY()>M41+365,"OUT","IN"))) -> OUT | P41: 2 | R41: O | T41: O
...

Sheet 설비 Master Sheet(미사용)
H1: 총 모델설비 | I1: =COUNTA(I8:I10001) -> 303 | J1: 셋업일 없고 워렌티 아웃 | K1: =I2-I3 -> 98 | N1: 월별 유상설비 수량 | O1: 1월 | P1: 2월 | Q1: 3월 | R1: 4월 | S1: 5월 | T1: 6월
C2: 모델명 및 설비 TYPE 기존 기입 데이터 참고하여 기입 | H2: 총 SN설비 | I2: =COUNTA(J8:J10001) -> 272 | O2: =COUNTIFS($M$8:$M$10001,"<=" & EOMONTH(DATE(2025,1,1),-12))+$K$1 -> 240 | P2: =COUNTIFS($M$8:$M$10001,"<=" & EOMONTH(DATE(2025,2,1),-12))+$K$1 -> 241 | Q2: =COUNTIFS($M$8:$M$10001,"<=" & EOMONTH(DATE(2025,3,1),-12))+$K$1 -> 245 | R2: =COUNTIFS($M$8:$M$10001,"<=" & EOMONTH(DATE(2025,4,1),-12))+$K$1 -> 250 | S2: =COUNTIFS($M$8:$M$10001,"<=" & EOMONTH(DATE(2025,5,1),-12))+$K$1 -> 250 | T2: =COUNTIFS($M$8:$M$10001,"<=" & EOMONTH(DATE(2025,6,1),-12))+$K$1 -> 254
H3: 셋업일 표시설비 | I3: =COUNTA(M8:M602) -> 174 | J3: 워렌티 인 | K3: =COUNTIF(O8:O10001,"IN") -> 6 | O3: 7월 | P3: 8월 | Q3: 9월 | R3: 10월 | S3: 11월 | T3: 12월
J4: 워렌티 아웃 | O4: =COUNTIFS($M$8:$M$10001,"<=" & EOMONTH(DATE(2025,7,1),-12))+$K$1 -> 255 | P4: =COUNTIFS($M$8:$M$10001,"<=" & EOMONTH(DATE(2025,8,1),-12))+$K$1 -> 258 | Q4: =COUNTIFS($M$8:$M$10001,"<=" & EOMONTH(DATE(2025,9,1),-12))+$K$1 -> 259 | R4: =COUNTIFS($M$8:$M$10001,"<=" & EOMONTH(DATE(2025,10,1),-12))+$K$1 -> 260 | S4: =COUNTIFS($M$8:$M$10001,"<=" & EOMONTH(DATE(2025,11,1),-12))+$K$1 -> 261 | T4: =COUNTIFS($M$8:$M$10001,"<=" & EOMONTH(DATE(2025,12,1),-12))+$K$1 -> 263
B5: ■ 종합사이트 Master Sheet
B6: No | C6: 상호 | D6: 지역 | E6: 상세위치 | F6: 공정 | G6: 사용가스 | H6: 호기 | I6: MODEL | J6: S/N | K6: TYPE | L6: 반입일 | M6: Set-Up일 | N6: 이설 Set-Up일 | O6: WARRENTY | P6: Inlet 사용port | Q6: 외부 Tank 사용 여부 | R6: Blower | S6: Heater 종류 | T6: 방문이력 | U6: 비고/특이사항
B8: 1 | C8: AND | D8: 안성 | I8: 507BWA | J8: M002622 | K8: HEAT-WET | O8: =IF(M8="","OUT",IF(TODAY()>M8+365,"OUT","IN")) -> OUT | T8: X | U8: 파워마스터에 설비 판매 한 것으로 추정
B9: 2 | C9: AP System | D9: 오산 | I9: 507BWA | J9: M002442 | K9: HEAT-WET | O9: =IF(M9="","OUT",IF(TODAY()>M9+365,"OUT","IN")) -> OUT | T9: X
B10: 3 | C10: BJ Power | D10: 대전 | I10: 507BW | K10: HEAT-WET | O10: =IF(M10="","OUT",IF(TODAY()>M10+365,"OUT","IN")) -> OUT | T10: X
B11: 4 | C11: JNK | D11: 마도 | I11: 601PW | J11: M001842 | K11: PLASMA | O11: =IF(M11="","OUT",IF(TODAY()>M11+365,"OUT","IN")) -> OUT | T11: X
I12: 507BWA | K12: HEAT-WET | O12: =IF(M12="","OUT",IF(TODAY()>M12+365,"OUT","IN")) -> OUT | T12: X
B13: 5 | C13: Kanc | D13: 수원 | H13: EP-1172 | I13: 1207BW | J13: M001021 | K13: HEAT-WET | O13: =IF(M13="","OUT",IF(TODAY()>M13+365,"OUT","IN")) -> OUT | T13: X
D14: 수원 | I14: MAT501BW | J14: 970516-GS-0116 | K14: HEAT-WET | O14: =IF(M14="","OUT",IF(TODAY()>M14+365,"OUT","IN")) -> OUT | T14: X
B15: 6 | C15: KEC | D15: 구미 | I15: 507BWA | J15: M001762 | K15: HEAT-WET | O15: =IF(M15="","OUT",IF(TODAY()>M15+365,"OUT","IN")) -> OUT | P15: 2 | Q15: X | R15: O | S15: 칸탈 | T15: O
I16: 507BWA | J16: M001985 | K16: HEAT-WET | O16: =IF(M16="","OUT",IF(TODAY()>M16+365,"OUT","IN")) -> OUT | P16: 3 | Q16: X | R16: O | S16: 칸탈 | T16: O
I17: 507BW | J17: 20050331-KE-1158 | K17: HEAT-WET | O17: =IF(M17="","OUT",IF(TODAY()>M17+365,"OUT","IN")) -> OUT | Q17: X | R17: O | S17: 칸탈 | T17: O
F18: HTO | I18: 507BW | J18: 20050331-KE-1159 | K18: HEAT-WET | O18: =IF(M18="","OUT",IF(TODAY()>M18+365,"OUT","IN")) -> OUT | P18: 1 | Q18: X | R18: O | S18: 칸탈 | T18: O
F19: CVD | I19: 507BW | J19: 20050331-KE-1160 | K19: HEAT-WET | O19: =IF(M19="","OUT",IF(TODAY()>M19+365,"OUT","IN")) -> OUT | Q19: X | R19: O | S19: 칸탈 | T19: O
F20: POLY | I20: 507BW | J20: 20050331-KE-1161 | K20: HEAT-WET | O20: =IF(M20="","OUT",IF(TODAY()>M20+365,"OUT","IN")) -> OUT | Q20: X | R20: O | S20: 칸탈 | T20: O
F21: CVD | I21: 507BW | J21: 20050331-KE-1162 | K21: HEAT-WET | O21: =IF(M21="","OUT",IF(TODAY()>M21+365,"OUT","IN")) -> OUT | Q21: X | R21: O | S21: 칸탈 | T21: O
F22: ETCH | I22: 507BW | J22: 20050331-KE-1164 | K22: HEAT-WET | O22: =IF(M22="","OUT",IF(TODAY()>M22+365,"OUT","IN")) -> OUT | Q22: X | R22: O | S22: 칸탈 | T22: O
F23: GAS ROOM | I23: 507BW | J23: 20050331-KE-1165 | K23: HEAT-WET | O23: =IF(M23="","OUT",IF(TODAY()>M23+365,"OUT","IN")) -> OUT | Q23: X | R23: O | S23: 칸탈 | T23: O | U23: 가스룸 설비 (2025.05.12 추가)
F24: CVD | I24: 1207BW | J24: 20051215-KE-1307 | K24: HEAT-WET | O24: =IF(M24="","OUT",IF(TODAY()>M24+365,"OUT","IN")) -> OUT | Q24: X | R24: O | S24: 칸탈 | T24: O
F25: CVD | I25: 507BWS | J25: M006188 | K25: HEAT-WET | L25: 44624 | M25: 44642 | O25: =IF(M25="","OUT",IF(TODAY()>M25+365,"OUT","IN")) -> OUT | P25: 2 | Q25: X | R25: O | S25: 칸탈 | T25: O
F26: TEOS | I26: 507BWS | J26: M006499 | K26: HEAT-WET | L26: 44845 | M26: 44853 | O26: =IF(M26="","OUT",IF(TODAY()>M26+365,"OUT","IN")) -> OUT | P26: 1 | Q26: X | R26: O | S26: 칸탈 | T26: O
B27: 7 | C27: KIST | D27: 서울 | I27: MAT501BW | K27: HEAT-WET | O27: =IF(M27="","OUT",IF(TODAY()>M27+365,"OUT","IN")) -> OUT | P27: 4 | Q27: X | R27: X | S27: SIC | T27: O
I28: MAT501BW | J28: 20020520-KT-549 | K28: HEAT-WET | O28: =IF(M28="","OUT",IF(TODAY()>M28+365,"OUT","IN")) -> OUT | P28: 4 | Q28: X | R28: X | S28: SIC | T28: O
I29: MAT501BW | J29: 20031012-KI-458 | K29: HEAT-WET | O29: =IF(M29="","OUT",IF(TODAY()>M29+365,"OUT","IN")) -> OUT | P29: 4 | Q29: X | R29: X | S29: SIC | T29: O
B30: 8 | C30: LG전자기술 연구소 | D30: 서울 우면동 | I30: 1207BWA | J30: M001919 | K30: HEAT-WET | M30: 43069 | O30: =IF(M30="","OUT",IF(TODAY()>M30+365,"OUT","IN")) -> OUT | P30: - | Q30: - | R30: - | S30: - | T30: O
I31: 507BWS | J31: M002615 | K31: HEAT-WET | M31: 43069 | O31: =IF(M31="","OUT",IF(TODAY()>M31+365,"OUT","IN")) -> OUT | P31: - | Q31: - | R31: - | S31: - | T31: O
B32: 9 | C32: LG 화학 기술연구원 | D32: 대전 | I32: 507BWA | J32: M002581 | K32: HEAT-WET | O32: =IF(M32="","OUT",IF(TODAY()>M32+365,"OUT","IN")) -> OUT | T32: X
I33: 1501HW | J33: M006175 | K33: HEAT-WET | L33: 44544 | M33: 44573 | O33: =IF(M33="","OUT",IF(TODAY()>M33+365,"OUT","IN")) -> OUT | P33: 2 | Q33: X | R33: X | S33: 칸탈 | T33: O
B34: 10 | C34: SK 머티리얼즈 | D34: 영주 | I34: 1207BW | J34: M002097 | K34: HEAT-WET | O34: =IF(M34="","OUT",IF(TODAY()>M34+365,"OUT","IN")) -> OUT | T34: X
I35: MAT501 | K35: HEAT-WET | O35: =IF(M35="","OUT",IF(TODAY()>M35+365,"OUT","IN")) -> OUT | T35: X
D36: 군산 | I36: 1207BW | J36: M002089 | K36: HEAT-WET | O36: =IF(M36="","OUT",IF(TODAY()>M36+365,"OUT","IN")) -> OUT | T36: X
B37: 11 | C37: PPI | D37: 광주 | I37: 507BWS | J37: M002260 | K37: HEAT-WET | O37: =IF(M37="","OUT",IF(TODAY()>M37+365,"OUT","IN")) -> OUT | T37: X
I38: MAT501BW | J38: 20030623-PP-595 | K38: HEAT-WET | O38: =IF(M38="","OUT",IF(TODAY()>M38+365,"OUT","IN")) -> OUT | T38: X
B39: 12 | C39: SFA | D39: 기흥 | I39: MI2500 | J39: M001817 | K39: HEAT-WET | O39: =IF(M39="","OUT",IF(TODAY()>M39+365,"OUT","IN")) -> OUT | T39: X
B40: 13 | C40: SK 이노베이션 | I40: FCTO2000W | J40: M002594 | K40: FCTO | O40: =IF(M40="","OUT",IF(TODAY()>M40+365,"OUT","IN")) -> OUT | T40: X
B41: 14 | C41: SMP 삼성정밀화학 | D41: 울산 | I41: 1207BWA | J41: M002613 | K41: HEAT-WET | O41: =IF(M41="","OUT",IF(TODAY()>M41+365,"OUT","IN")) -> OUT | T41: X
...

Sheet 철거 및 이설 장비

Sheet 담당자
B2: 업체명 | C2: 담당자 | D2: 직급 | E2: 연락처 | F2: 이메일 주소
B3: AND
B4: AP System
B5: BJ Power
B6: JNK
B7: Kanc
B8: KEC | C8: 김영효 | D8: 미확인 | E8: 010-5604-0567
C9: 임영만 | D9: 기사 | E9: 010 7188 2453
C10: 김상훈 | D10: 미확인 | E10: 010-9286-6538 | F10: kimsh@kec.co.kr
C11: 박성준 | D11: 사원 | E11: 010-7212-3245
C12: 박재현 | D12: 미확인 | E12: 010-4899-2528
C13: 정성욱 | D13: 미확인 | E13: 010-3087-0312
C14: 정현택 | D14: 기사 | E14: 010-5171-6170
B15: KIST | C15: 남기훈 | D15: 미확인 | E15: 010-8863-7887
B16: LG전자기술 연구소
B17: LG 화학 기술연구원 | C17: 강수희 | D17: 책임 | E17: 010-6275-0356 | F17: kennt@lgchem.com
B18: SK 머티리얼즈
B20: PPI
B21: SFA
B22: SK 이노베이션
B23: SMP 삼성정밀화학
B24: STX 솔라
B25: 가천대학교 | C25: 김기락 | E25: 010-2654-8061
C26: 이동운 | D26: 학생 | E26: 010-9270-1386 | F26: grw04214@gachon.ac.kr
C27: 이동현 | D27: 학생 | E27: 010-4817-8769
C28: 조의식 | D28: 교수 | F28: es.cho@gachon.ac.kr
B29: 경북과학기술원 | C29: 손대호 | D29: 연구원 | E29: 010-6370-4203
B30: 경북대학교 반도체 융합 기술 연구원
B31: 광전자
B32: 광주과학기술원
B33: 국가 핵융합연구소
B34: 국제일렉트릭코리아 (오산) | C34: 이연호 | D34: 영업팀 | E34: 031-8015-8389
B35: 국제일렉트릭코리아 (진위) | C35: 박종선 | D35: PL | E35: 010-3354-5935 | F35: jongsun.park@kokusai-electric.com
B36: 나노스 | C36: 박경환 | D36: 과장 | E36: 010-5769-0817
C37: 석원빈 | D37: 주임 | E37: 010-2445-7838 | F37: tututu1425@nanosm.com
C38: 김명래 | D38: 주임 | E38: 010-6423-8015
B39: 뉴파워플라즈마
B40: 데크 | C40: 권향주 | D40: 미확인 | E40: 010-2686-3676 | F40: khj86@dacc21.com
B41: 동우 화인켐 | C41: 김재욱 | D41: 선임 | E41: 010-4767-3167 | F41: jaewookkim@dwchem.co.kr
C42: 윤익진 | D42: 선임 | E42: 010-6296-5088 | F42: yoonij@dwchem.co.kr
...

Sheet 작업프로세스

Sheet KPI 관리고객사
B2: 상호 | C2: 지역 | D2: MODEL | E2: MODEL별 수량 | F2: 업체별 MODEL 함산수량 | G2: 우선순위 | H2: 방문이력 | I2: 담당자 | J2: 담당자 연락처
B3: 온세미 컨덕터 | C3: 부천 | D3: 507BW, 507BWA, P260HW, 507BWS, 1701HW, MI2500BW | E3: 507BW 1대, 507BWA 5대, P260HW 1대, 507BWS 9대, 1701HW 24대, MI2500BW 4대 | F3: 44 | G3: 1 | H3: O | I3: 윤상우 선임 | J3: 010-6797-4525
B4: 파워마스터 | C4: 충북 오창 | D4: 507BWA | E4: 507BWA 36대 | F4: 36 | G4: 2 | H4: O | I4: 김선일 과장 | J4: 010-2747-7571
B5: 동우 화인켐 | C5: 평택 | D5: 1207BWA , 603PW | E5: 1207BWA 12대 , 603PW 8대 | F5: 20 | G5: 3 | H5: O | I5: 김재욱 선임 | J5: 010-4767-3167
B6: 테스 | C6: 용인 | D6: 507BWA, 1207BWA | E6: 507BWA 5대, 1207BWA 9대 | F6: 14 | G6: 4 | H6: O | I6: 조석정 | J6: 010-4017-2793
B7: KEC | C7: 구미 | D7: 507BWA, 507BW, 1207BW, 507BWS | E7: 507BWA 2대, 507BW 6대, 1207BW 1대, 507BWS 2대 | F7: 11 | G7: 5 | H7: O | I7: 임영만 기사 | J7: 010 7188 2453
B8: LG전자(마곡) | C8: 서울/마곡 | D8: 1207BW, ION, 601WPW, 1207BWA, MI2500BW, 507BWS | E8: 1207BW 1대, ION 2대, 601WPW 2대, 1207BWA 1대, MI2500BW 1대, 507BWS 1대 | F8: 8 | G8: 6 | H8: O | I8: 안홍준 선임 | J8: 010-5097-3436
B9: 동부하이텍 | C9: 부천 | D9: 507BWS | E9: 507BWS 7대 | F9: 7 | G9: 7 | H9: O | I9: 박민규 선임 | J9: 010-5097-3436
B10: (주)미래보 | C10: 평택 | D10: 507BWS, 1207BWA, 1701HW | E10: 507BWS 2대, 1207BWA 2대, 1701HW 2대 | F10: 6 | G10: 8 | H10: O | I10: 문성식 과장 | J10: 010 3949 3554
B11: 주성 RND 센터 | C11: 용인 | D11: 508BWA | E11: 508BWA 2대, 1207BWA 3대 | F11: 5 | G11: 9 | H11: O | I11: 소중원 PL | J11: 010-5446-4182
B12: MEMC코리아 | C12: 천안 | D12: FCTO700W, 509HW, 502W | E12: FCTO700W 3대, 509HW 1대, 502W 1대 | F12: 5 | G12: 10 | H12: O | I12: 이춘기 수석 | J12: 010-8755-3531
B13: 메카로 | C13: 음성 (성본) | D13: MI2500BW | E13: MI2500BW 5대 | F13: 5 | G13: 11 | H13: O | I13: 홍준철 이사 | J13: 010-9311-1251
B14: 삼성종합기술원 | C14: 수원 | D14: 507BWA, FCTO703W | E14: 507BWA 2대, FCTO703W 2대 | F14: 4 | G14: 12 | H14: O | I14: 유민석 프로 | J14: 010-7577-8913
... B18: 국제일렉트릭코리아 | C18: 오산 | D18: MI2000, MAT501BW | E18: MI2000 1대, MAT501BW 2대 | F18: 3 | G18: 16 | H18: X | I18: 이연호 영업팀 | J18: 031-8015-8389
B19: SK 머티리얼즈 | C19: 영주 | D19: 1207BW, MAT501 | E19: 1207BW 2대, MAT501 1대 | F19: 3 | G19: 17 | H19: X
B20: 주성 | C20: 경기 광주 | D20: MI2000, 1207BW, MAT501BW | E20: MI2000 1대, 1207BW 1대, MAT501BW 1대 | F20: 3 | G20: 18 | H20: X
B21: 나노스 | C21: 성남 | D21: MAT501BW, 507BWS | E21: MAT501BW 1대, 507BWS 1대 | F21: 2 | G21: 19 | H21: O | I21: 석원빈 주임 | J21: 010-2445-7838
B22: 한국소화화학 | C22: 안성 | D22: FCTO3001W | E22: FCTO3001W 2대 | F22: 2 | G22: 20 | H22: O | I22: 나영복 차장 | J22: 010-3146-1834
B23: LG 화학 기술연구원 | C23: 대전 | D23: 507BWA, 1501HW | E23: 507BWA 1대, 1501HW 1대 | F23: 2 | G23: 21 | H23: X | I23: 강수희 책임 | J23: 010-6275-0356
B24: 경북과학기술원 | C24: 대구 | D24: 1207BWA | E24: 1207BWA 2대 | F24: 2 | G24: 22 | H24: O | I24: 손대효 연구원 | J24: 010-6370-4203
B25: 한국생산기술연구원 | C25: 안산 | D25: 507BWA | E25: 507BWA 2대 | F25: 2 | G25: 23 | H25: O | I25: 변철수 박사 | J25: 010-6875-8454
B26: LG전자기술 연구소 | C26: 서울 우면동 | D26: 1207BWA, 507BWS | E26: 1207BWA 1대, 507BWS 1대 | F26: 2 | G26: 24 | H26: O
B27: PPI | C27: 광주 | D27: 507BWS, MAT501BW | E27: 507BWS 1대, MAT501BW 1대 | F27: 2 | G27: 25 | H27: X
B28: STX 솔라 | C28: 구미 | D28: 507BWA, 403W | E28: 507BWA 1대, 403W 1대 | F28: 2 | G28: 26 | H28: X
B29: 엘오티씨이에스(클린팩터스) | C29: 오산 | D29: 507BWS | E29: 50BWS 1대 | F29: 1 | G29: 27 | H29: O | I29: 김형준 선임 | J29: 010 2017 6237
B30: ㈜아르케 | C30: 용인 | D30: MI2000BW | E30: MI2000BW 1대 | F30: 1 | G30: 28 | H30: O | I30: 노병훈 이사 | J30: 010 5555 0855
B31: 비아트론 | C31: 수원 | D31: MI2000BW | E31: MI2000BW 1대 | F31: 1 | G31: 29 | H31: O | I31: 이남천 차장 | J31: 010 8702 3106
B32: 피니사르대전 유한회사 | C32: 대전 | D32: 507BWS | E32: 507BWS 1대 | F32: 1 | G32: 30 | H32: O | I32: 이영수 부장 | J32: 010-2030-8764
B33: 데크카본 | C33: 전주 | D33: MI2500BW | E33: MI2500BW 1대 | F33: 1 | G33: 31 | H33: O | I33: 권향주 책임 | J33: 010-2686-3676
B34: 트리노테크놀로지 | C34: 서울 | D34: 507BW | E34: 507BW 1대 | F34: 1 | G34: 32 | H34: O | I34: 강석원 부장 | J34: 010-3005-1401
B35: 선익시스템 | C35: 수원 | D35: 1207BWA | E35: 1207BWA 1대 | F35: 1 | G35: 33 | H35: O | I35: 김영석 대리 | J35: 010-3139-9413
B36: 휴민텍 | C36: 천안 | D36: 502W | E36: 502W 1대 | F36: 1 | G36: 34 | H36: O | I36: 최영락 선임 | J36: 010-3895-7039
B37: 재료연구소 | C37: 창원 | D37: 507BWA | E37: 507BWA 1대 | F37: 1 | G37: 35 | H37: X | I37: 권정대 책임 | J37: 010-4525-8268
B38: SK실트론 | C38: 구미 | D38: 508BWA | E38: 508BWA 1대 | F38: 1 | G38: 36 | H38: O | I38: 이창규 프로 | J38: 010-4643-9911
B39: 조선대학교 | C39: 광주 | D39: 507BWA | E39: 507BWA 1대 | F39: 1 | G39: 37 | H39: O | I39: 최태용 | J39: 010-4913-4002
B40: 한국화학연구원 | C40: 대전 | D40: 507BW | E40: 507BW 1대 | F40: 1 | G40: 38 | H40: O | I40: 연구원 | J40: 010-5306-5759
... B52: 한화큐셀 (HTS) | C52: 진천 | D52: 601WPW | E52: 601WPW 1대 | F52: 1 | G52: 50 | H52: O | I52: 김상우 조장 | J52: 010-9944-1003
B53: AP System | C53: 오산 | D53: 507BWA | E53: 507BWA 1대 | F53: 1 | G53: 51 | H53: X
B54: BJ Power | C54: 대전 | D54: 507BW | E54: 507BW 1대 | F54: 1 | G54: 52 | H54: X
B55: JNK | C55: 마도 | D55: 601PW | E55: 601PW 1대 | F55: 1 | G55: 53 | H55: X
...

Sheet Sheet1
B3: 작업
B4: 파트

Sheet New Alarm 및 사용Part 이력
AP1: 불합리
A2: NO. | B2: 구분 | C2: 부서 | D2: 고객사 | E2: 사업부 | F2: SITE | G2: 라인 | H2: MAIN 공정 | I2: 세부공정 | J2: 설비호기 | K2: CHAMBER | L2: S/N | M2: MODEL | N2: TYPE | O2: TURN ON | P2: 작업일자 | Q2: 시작시간 | R2: 종료시간 | S2: 작업시간 | T2: 작업인원 | U2: 작업공수 | V2: 대분류 | W2: 소분류 | X2: 문제 (현상) | Y2: 원인 | Z2: Action (조치) (내부 PM만 설비개방) | AA2: 파트구분 (파트,수리품) | AB2: 파트명 | AC2: 품번 | AD2: 고객사 코드 | AE2: 수량 | AF2: WARRANTY | AG2: 사용일 | AH2: 유/무상 | AI2: 원가 (erp) | AJ2: 판가 (erp) | AK2: 규격 | AL2: WARRENTY Out 여부 | AM2: 이전 방문일 | AN2: 월 | AO2: 경과일 | AP2: 신규설비 초기불량시 (O) | AQ2: 유/무상/ (업체)재고
A3: 11 | B3: 작업 | C3: CS4부 | D3: 동우화인켐 | E3: - | F3: 종합사이트 | G3: 2공장 | H3: CVD | I3: CVD | J3: 4-A | K3: - | L3: M008222 | M3: 603PW | N3: Plasma | O3: 45951 | P3: 46035 | Q3: 0.39583333 | R3: 0.6875 | S3: =R3-Q3 -> 0.29166667 | T3: 3 | U3: =S3*T3 -> 0.875 | V3: PM | W3: TBM | X3: 정기PM 및 Drain 개선 | Y3: 정기PM 및 Drain Valve안열림현상 | Z3: 내부 PM | AA3: - | AB3: 인건비 | AC3: - | AD3: - | AE3: 3 | AF3: 1년 | AG3: - | AH3: 무상 | AI3: - | AJ3: - | AK3: - | AL3: =IF(O3="","OUT",IF(TODAY()>O3+365,"OUT","IN")) -> IN | AM3: 46021 | AN3: =MONTH(P3) -> 1 | AO3: =P3-AM3 -> 14 | AQ3: 무상
A4: 12 | B4: 파트 | C4: CS4부 | D4: 동우화인켐 | E4: - | F4: 종합사이트 | G4: 2공장 | H4: CVD | I4: CVD | J4: 4-A | K4: - | L4: M008222 | M4: 603PW | N4: Plasma | O4: 45951 | P4: 46035 | Q4: 0.39583333 | R4: 0.6875 | S4: =R4-Q4 -> 0.29166667 | T4: 3 | U4: =S4*T4 -> 0.875 | V4: PM | W4: TBM | X4: 정기PM 및 Drain 개선 | Y4: 정기PM 및 Drain Valve안열림현상 | Z4: SMPS 설치 | AA4: 파트 | AB4: SMPS | AC4: 901-DD1-M1 | AD4: - | AE4: 1 | AF4: 1년 | AG4: - | AH4: 무상 | AI4: - | AJ4: - | AK4: NDR-240-24 | AL4: =IF(O4="","OUT",IF(TODAY()>O4+365,"OUT","IN")) -> IN | AM4: 46021 | AN4: =MONTH(P4) -> 1 | AO4: =P4-AM4 -> 14 | AQ4: 무상
A5: 13 | B5: 작업 | C5: CS4부 | D5: 원익머트리얼즈 | E5: - | F5: 종합사이트 | G5: - | H5: - | I5: - | J5: - | K5: - | L5: M008028 | M5: 1501HW | N5: H/W | O5: 45989 | P5: 46031 | Q5: 0.39583333 | R5: 0.45833333 | S5: =R5-Q5 -> 0.0625 | T5: 2 | U5: =S5*T5 -> 0.125 | V5: PM | W5: 개선 | X5: PLC OUT CARD 장착 및 Program 변경 | Y5: Exhaust Pressure Data를 Main Control Panel의 PLC로 출력 | Z5: PLC OUT CARD 장착 | AA5: - | AB5: 인건비 | AC5: - | AD5: - | AE5: 2 | AF5: 1년 | AG5: - | AH5: 무상 | AI5: - | AJ5: - | AK5: - | AL5: =IF(O5="","OUT",IF(TODAY()>O5+365,"OUT","IN")) -> IN | AM5: 45996 | AN5: =MONTH(P5) -> 1 | AO5: =P5-AM5 -> 35 | AQ5: 무상
A6: 14 | B6: 파트 | C6: CS4부 | D6: 원익머트리얼즈 | E6: - | F6: 종합사이트 | G6: - | H6: - | I6: - | J6: - | K6: - | L6: M008028 | M6: 1501HW | N6: H/W | O6: 45989 | P6: 46031 | Q6: 0.39583333 | R6: 0.45833333 | S6: =R6-Q6 -> 0.0625 | T6: 2 | U6: =S6*T6 -> 0.125 | V6: PM | W6: 개선 | X6: PLC OUT CARD 장착 및 Program 변경 | Y6: Exhaust Pressure Data를 Main Control Panel의 PLC로 출력 | Z6: PLC OUT CARD 장착 | AA6: 파트 | AB6: PLC ANALOG UNIT | AC6: 901-047-051 | AD6: - | AE6: 1 | AF6: 1년 | AG6: - | AH6: 무상 | AI6: - | AJ6: - | AK6: CJ1W-MAD42 | AL6: =IF(O6="","OUT",IF(TODAY()>O6+365,"OUT","IN")) -> IN | AM6: 45996 | AN6: =MONTH(P6) -> 1 | AO6: =P6-AM6 -> 35 | AQ6: 무상
A7: 15 | B7: 파트 | C7: CS4부 | D7: 원익머트리얼즈 | E7: - | F7: 종합사이트 | G7: - | H7: - | I7: - | J7: - | K7: - | L7: M008028 | M7: 1501HW | N7: H/W | O7: 45989 | P7: 46031 | Q7: 0.39583333 | R7: 0.45833333 | S7: =R7-Q7 -> 0.0625 | T7: 2 | U7: =S7*T7 -> 0.125 | V7: PM | W7: 개선 | X7: Wet Temp 상승 관련 | Y7: Exhaust Nozzle Assy 교체 | Z7: Exhaust Nozzle Assy 교체 | AA7: 파트 | AB7: EXHAUST NOZZLE ASSY | AC7: 1501-160-S12-03 | AD7: - | AE7: 1 | AF7: 1년 | AG7: - | AH7: 무상 | AI7: - | AJ7: - | AK7: 3/8" NOZZLE TIP | AL7: =IF(O7="","OUT",IF(TODAY()>O7+365,"OUT","IN")) -> IN | AM7: 45996 | AN7: =MONTH(P7) -> 1 | AO7: =P7-AM7 -> 35 | AQ7: 무상
A8: 16 | B8: 작업 | C8: CS4부 | D8: 원익머트리얼즈 | E8: - | F8: 종합사이트 | G8: - | H8: - | I8: - | J8: - | K8: - | L8: M008027 | M8: 1501HW | N8: H/W | O8: 45989 | P8: 46031 | Q8: 0.45833333 | R8: 0.54166667 | S8: =R8-Q8 -> 0.083333333 | T8: 2 | U8: =S8*T8 -> 0.16666667 | V8: PM | W8: 개선 | X8: Wet Temp 상승 관련 | Y8: Exhaust Nozzle Assy 교체 및 SCRUBBER OPEN | Z8: Exhaust Nozzle Assy 교체 | AA8: - | AB8: 인건비 | AC8: - | AD8: - | AE8: 2 | AF8: 1년 | AG8: - | AH8: 무상 | AI8: - | AJ8: - | AK8: - | AL8: =IF(O8="","OUT",IF(TODAY()>O8+365,"OUT","IN")) -> IN | AM8: 46030 | AN8: =MONTH(P8) -> 1 | AO8: =P8-AM8 -> 1 | AQ8: 무상
A9: 17 | B9: 파트 | C9: CS4부 | D9: 원익머트리얼즈 | E9: - | F9: 종합사이트 | G9: - | H9: - | I9: - | J9: - | K9: - | L9: M008027 | M9: 1501HW | N9: H/W | O9: 45989 | P9: 46031 | Q9: 0.45833333 | R9: 0.54166667 | S9: =R9-Q9 -> 0.083333333 | T9: 2 | U9: =S9*T9 -> 0.16666667 | V9: PM | W9: 개선 | X9: Wet Temp 상승 관련 | Y9: Exhaust Nozzle Assy 교체 및 SCRUBBER OPEN | Z9: Exhaust Nozzle Assy 교체 | AA9: 파트 | AB9: EXHAUST NOZZLE ASSY | AC9: 1501-160-S12-03 | AD9: - | AE9: 1 | AF9: 1년 | AG9: - | AH9: 무상 | AI9: - | AJ9: - | AK9: 3/8" NOZZLE TIP | AL9: =IF(O9="","OUT",IF(TODAY()>O9+365,"OUT","IN")) -> IN | AM9: 46030 | AN9: =MONTH(P9) -> 1 | AO9: =P9-AM9 -> 1 | AQ9: 무상
A10: 18 | B10: 작업 | C10: CS4부 | D10: 레조낙코리아 | E10: - | F10: 종합사이트 | G10: - | H10: C2F6 VENT | I10: C2F6 VENT | J10: A호기 | K10: - | L10: M006133 | M10: FCTO3001 | N10: Cartridge | O10: 44727 | P10: 46036 | Q10: 0.39583333 | R10: 0.6875 | S10: =R10-Q10 -> 0.29166667 | T10: 4 | U10: =S10*T10 -> 1.1666667 | V10: BM | W10: ALARM | X10: Heater Temp Low | Y10: Heater 단선 | Z10: 내부 PM | AA10: - | AB10: 인건비 | AC10: - | AD10: - | AE10: 4 | AF10: 1년 | AG10: - | AH10: 유상 | AI10: - | AJ10: - | AK10: - | AL10: =IF(O10="","OUT",IF(TODAY()>O10+365,"OUT","IN")) -> OUT | AM10: 45301 | AN10: =MONTH(P10) -> 1 | AO10: =P10-AM10 -> 735 | AQ10: 유상
A11: 19 | B11: 파트 | C11: CS4부 | D11: 레조낙코리아 | E11: - | F11: 종합사이트 | G11: - | H11: C2F6 VENT | I11: C2F6 VENT | J11: A호기 | K11: - | L11: M006133 | M11: FCTO3001 | N11: Cartridge | O11: 44727 | P11: 46036 | Q11: 0.39583333 | R11: 0.6875 | S11: =R11-Q11 -> 0.29166667 | T11: 4 | U11: =S11*T11 -> 1.1666667 | V11: BM | W11: ALARM | X11: Heater Temp Low | Y11: Heater 단선 | Z11: Cartridge 교체 | AA11: 파트 | AB11: CARTRIDGE ASSY | AC11: FC3001W-110-A00 -01-P | AD11: - | AE11: 1 | AF11: 1년 | AG11: 1309 | AH11: 유상 | AI11: - | AJ11: - | AK11: FCTO3001W/Spare | AL11: =IF(O11="","OUT",IF(TODAY()>O11+365,"OUT","IN")) -> OUT | AM11: 45301 | AN11: =MONTH(P11) -> 1 | AO11: =P11-AM11 -> 735 | AQ11: 유상
A12: 20 | B12: 파트 | C12: CS4부 | D12: 레조낙코리아 | E12: - | F12: 종합사이트 | G12: - | H12: C2F6 VENT | I12: C2F6 VENT | J12: A호기 | K12: - | L12: M006133 | M12: FCTO3001 | N12: Cartridge | O12: 44727 | P12: 46036 | Q12: 0.39583333 | R12: 0.6875 | S12: =R12-Q12 -> 0.29166667 | T12: 4 | U12: =S12*T12 -> 1.1666667 | V12: BM | W12: ALARM | X12: Heater Temp Low | Y12: Heater 단선 | Z12: Cartridge 교체 | AA12: 파트 | AB12: CENTER-RING | AC12: 903-010-000 | AD12: - | AE12: 4 | AF12: 1년 | AG12: - | AH12: 무상 | AI12: - | AJ12: - | AK12: NW50-오링 포함 | AL12: =IF(O12="","OUT",IF(TODAY()>O12+365,"OUT","IN")) -> OUT | AM12: 45301 | AN12: =MONTH(P12) -> 1 | AO12: =P12-AM12 -> 735 | AQ12: 무상
A13: 21 | B13: 작업 | C13: CS4부 | D13: 온세미컨덕터코리아 | E13: - | F13: 종합사이트 | G13: EPI | H13: - | I13: - | J13: 전설비 | K13: - | L13: 전설비 | M13: 전설비 | N13: H/W | O13: - | P13: 46024 | Q13: 0.39583333 | R13: 0.61805556 | S13: =R13-Q13 -> 0.22222222 | T13: 2 | U13: =S13*T13 -> 0.44444444 | V13: PM | W13: 점검 | X13: 전 설비 점검 | Y13: 전 설비 점검 | Z13: 설비 점검 | AA13: - | AB13: 인건비 | AC13: - | AD13: - | AE13: 2 | AF13: 1년 | AG13: - | AH13: 무상 | AI13: - | AJ13: - | AK13: - | AL13: =IF(O13="","OUT",IF(TODAY()>O13+365,"OUT","IN")) -> #VALUE! | AM13: 46020 | AN13: =MONTH(P13) -> 1 | AO13: =P13-AM13 -> 4 | AQ13: 무상
A14: 22 | B14: 작업 | C14: CS4부 | D14: 가천대학교 | E14: - | F14: 종합사이트 | G14: - | H14: - | I14: - | J14: - | K14: - | L14: M007617 | M14: 507BWS | N14: H/W | O14: 45818 | P14: 46024 | Q14: 0.625 | R14: 0.66666667 | S14: =R14-Q14 -> 0.041666667 | T14: 2 | U14: =S14*T14 -> 0.083333333 | V14: BM | W14: ALARM | X14: Water Leak Alarm 발생 | Y14: Water Leak Sesnsor 저항 Fail로 추정 | Z14: 저항교체 | AA14: - | AB14: 인건비 | AC14: - | AD14: - | AE14: 2 | AF14: 1년 | AG14: 206 | AH14: 무상 | AI14: - | AJ14: - | AK14: - | AL14: =IF(O14="","OUT",IF(TODAY()>O14+365,"OUT","IN")) -> IN | AM14: 46020 | AN14: =MONTH(P14) -> 1 | AO14: =P14-AM14 -> 4 | AQ14: 무상
A15: 23 | B15: 파트 | C15: CS4부 | D15: 가천대학교 | E15: - | F15: 종합사이트 | G15: - | H15: - | I15: - | J15: - | K15: - | L15: M007617 | M15: 507BWS | N15: H/W | O15: 45818 | P15: 46024 | Q15: 0.625 | R15: 0.66666667 | S15: =R15-Q15 -> 0.041666667 | T15: 2 | U15: =S15*T15 -> 0.083333333 | V15: BM | W15: ALARM | X15: Water Leak Alarm 발생 | Y15: Water Leak Sesnsor 저항 Fail로 추정 | Z15: 저항교체 | AA15: 파트 | AB15: 저항 | AC15: - | AD15: - | AE15: 1 | AF15: 1년 | AG15: 206 | AH15: 무상 | AI15: - | AJ15: - | AK15: - | AL15: =IF(O15="","OUT",IF(TODAY()>O15+365,"OUT","IN")) -> IN | AM15: 46020 | AN15: =MONTH(P15) -> 1 | AO15: =P15-AM15 -> 4 | AQ15: 무상
A16: 24 | B16: 작업 | C16: CS4부 | D16: 주성 RND 센터 | E16: - | F16: 종합사이트 | G16: Sub Fab | H16: - | I16: - | J16: - | K16: - | L16: M008322 | M16: 508BWA | N16: H/W | O16: - | P16: 46027 | Q16: 0.41666667 | R16: 0.47916667 | S16: =R16-Q16 -> 0.0625 | T16: 2 | U16: =S16*T16 -> 0.125 | V16: 기타 | W16: SET UP | X16: 신규설비 자리이동 및 바퀴탈착 | Y16: 신규설비 자리이동 및 바퀴탈착 | Z16: 설비 이동 및 바퀴탈착 | AA16: - | AB16: 인건비 | AC16: - | AD16: - | AE16: 2 | AF16: - | AG16: - | AH16: 무상 | AI16: - | AJ16: - | AK16: - | AL16: =IF(O16="","OUT",IF(TODAY()>O16+365,"OUT","IN")) -> #VALUE! | AM16: 46020 | AN16: =MONTH(P16) -> 1 | AO16: =P16-AM16 -> 7 | AQ16: 무상
A17: 25 | B17: 작업 | C17: CS4부 | D17: 온세미컨덕터코리아 | E17: - | F17: 종합사이트 | G17: EPI | H17: - | I17: - | J17: 전설비 | K17: - | L17: 전설비 | M17: 전설비 | N17: H/W | O17: - | P17: 46027 | Q17: 0.39583333 | R17: 0.61805556 | S17: =R17-Q17 -> 0.22222222 | T17: 2 | U17: =S17*T17 -> 0.44444444 | V17: PM | W17: 점검 | X17: 전 설비 점검 | Y17: 전 설비 점검 | Z17: 설비 점검 | AA17: - | AB17: 인건비 | AC17: - | AD17: - | AE17: 2 | AF17: 1년 | AG17: - | AH17: 무상 | AI17: - | AJ17: - | AK17: - | AL17: =IF(O17="","OUT",IF(TODAY()>O17+365,"OUT","IN")) -> #VALUE! | AM17: 46024 | AN17: =MONTH(P17) -> 1 | AO17: =P17-AM17 -> 3 | AQ17: 무상
A18: 26 | B18: 작업 | C18: CS4부 | D18: 가천대학교 | E18: - | F18: 종합사이트 | G18: - | H18: - | I18: - | J18: - | K18: - | L18: M007617 | M18: 507BWS | N18: H/W | O18: 45818 | P18: 46027 | Q18: 0.41666667 | R18: 0.5 | S18: =R18-Q18 -> 0.083333333 | T18: 2 | U18: =S18*T18 -> 0.16666667 | V18: PM | W18: CBM | X18: Water Leak Alarm 발생 | Y18: Exhaust 결로로 인한 Water Leak 발생 | Z18: 결로테이프 작업 | AA18: - | AB18: 인건비 | AC18: - | AD18: - | AE18: 2 | AF18: 1년 | AG18: 209 | AH18: 무상 | AI18: - | AJ18: - | AK18: - | AL18: =IF(O18="","OUT",IF(TODAY()>O18+365,"OUT","IN")) -> IN | AM18: 46024 | AN18: =MONTH(P18) -> 1 | AO18: =P18-AM18 -> 3 | AQ18: 무상
A19: 27 | B19: 파트 | C19: CS4부 | D19: 가천대학교 | E19: - | F19: 종합사이트 | G19: - | H19: - | I19: - | J19: - | K19: - | L19: M007617 | M19: 507BWS | N19: H/W | O19: 45818 | P19: 46027 | Q19: 0.41666667 | R19: 0.5 | S19: =R19-Q19 -> 0.083333333 | T19: 2 | U19: =S19*T19 -> 0.16666667 | V19: PM | W19: CBM | X19: Water Leak Alarm 발생 | Y19: Exhaust 결로로 인한 Water Leak 발생 | Z19: 결로테이프 작업 | AA19: 파트 | AB19: 결로테이프 | AC19: - | AD19: - | AE19: 1 | AF19: 1년 | AG19: 209 | AH19: 무상 | AI19: - | AJ19: - | AK19: - | AL19: =IF(O19="","OUT",IF(TODAY()>O19+365,"OUT","IN")) -> IN | AM19: 46024 | AN19: =MONTH(P19) -> 1 | AO19: =P19-AM19 -> 3 | AQ19: 무상
A20: 28 | B20: 작업 | C20: CS4부 | D20: 동우화인켐 | E20: - | F20: 종합사이트 | G20: 2공장 | H20: CVD | I20: CVD | J20: 6-A | K20: - | L20: M008230 | M20: 603PW | N20: Plasma | O20: 45974 | P20: 46028 | Q20: 0.39583333 | R20: 0.52083333 | S20: =R20-Q20 -> 0.125 | T20: 2 | U20: =S20*T20 -> 0.25 | V20: PM | W20: CBM | X20: Water Leak Alarm 발생 | Y20: Circulation Supply Nozzle 부식발생 | Z20: 내부 PM | AA20: - | AB20: 인건비 | AC20: - | AD20: - | AE20: 2 | AF20: 1년 | AG20: 54 | AH20: 무상 | AI20: - | AJ20: - | AK20: MAT603PW | AL20: =IF(O20="","OUT",IF(TODAY()>O20+365,"OUT","IN")) -> IN | AM20: 46021 | AN20: =MONTH(P20) -> 1 | AO20: =P20-AM20 -> 7 | AQ20: 무상
A21: 29 | B21: 파트 | C21: CS4부 | D21: 동우화인켐 | E21: - | F21: 종합사이트 | G21: 2공장 | H21: CVD | I21: CVD | J21: 6-A | K21: - | L21: M008230 | M21: 603PW | N21: Plasma | O21: 45974 | P21: 46028 | Q21: 0.39583333 | R21: 0.52083333 | S21: =R21-Q21 -> 0.125 | T21: 2 | U21: =S21*T21 -> 0.25 | V21: PM | W21: CBM | X21: Water Leak Alarm 발생 | Y21: Circulation Supply Nozzle 부식발생 | Z21: Nozzle 교체 | AA21: 파트 | AB21: Nozzle Supply Assy | AC21: 603P-140-S04-04 | AD21: - | AE21: 1 | AF21: 1년 | AG21: 54 | AH21: 무상 | AI21: - | AJ21: - | AK21: MAT603PW | AL21: =IF(O21="","OUT",IF(TODAY()>O21+365,"OUT","IN")) -> IN | AM21: 46021 | AN21: =MONTH(P21) -> 1 | AO21: =P21-AM21 -> 7 | AQ21: 무상
A22: 30 | B22: 파트 | C22: CS4부 | D22: 동우화인켐 | E22: - | F22: 종합사이트 | G22: 2공장 | H22: CVD | I22: CVD | J22: 6-A | K22: - | L22: M008230 | M22: 603PW | N22: Plasma | O22: 45974 | P22: 46028 | Q22: 0.39583333 | R22: 0.52083333 | S22: =R22-Q22 -> 0.125 | T22: 2 | U22: =S22*T22 -> 0.25 | V22: PM | W22: CBM | X22: Water Leak Alarm 발생 | Y22: 원형 Wet Nozzle Tip의 나사탭부분 부식으로 Tip 빠짐 현상 | Z22: Nozzle 교체 | AA22: 파트 | AB22: WET NOZZLE ASSY | AC22: 603P-140-S12-03 | AD22: - | AE22: 1 | AF22: 1년 | AG22: 54 | AH22: 무상 | AI22: - | AJ22: - | AK22: MAT603PW | AL22: =IF(O22="","OUT",IF(TODAY()>O22+365,"OUT","IN")) -> IN | AM22: 46021 | AN22: =MONTH(P22) -> 1 | AO22: =P22-AM22 -> 7 | AQ22: 무상
A23: 31 | B23: 파트 | C23: CS4부 | D23: 동우화인켐 | E23: - | F23: 종합사이트 | G23: 2공장 | H23: CVD | I23: CVD | J23: 6-A | K23: - | L23: M008230 | M23: 603PW | N23: Plasma | O23: 45974 | P23: 46028 | Q23: 0.39583333 | R23: 0.52083333 | S23: =R23-Q23 -> 0.125 | T23: 2 | U23: =S23*T23 -> 0.25 | V23: PM | W23: CBM | X23: Water Leak Alarm 발생 | Y23: Wet Nozzle Tip의 나사탭부분 부식으로 Tip 빠짐 현상 | Z23: Nozzle 교체 | AA23: 파트 | AB23: WET NOZZLE ASSY | AC23: 603P-140-S05-02 | AD23: - | AE23: 1 | AF23: 1년 | AG23: 54 | AH23: 무상 | AI23: - | AJ23: - | AK23: MAT603PW_IFKM | AL23: =IF(O23="","OUT",IF(TODAY()>O23+365,"OUT","IN")) -> IN | AM23: 46021 | AN23: =MONTH(P23) -> 1 | AO23: =P23-AM23 -> 7 | AQ23: 무상
A24: 32 | B24: 작업 | C24: CS4부 | D24: 동우화인켐 | E24: - | F24: 종합사이트 | G24: 2공장 | H24: CVD | I24: CVD | J24: 6-C | K24: - | L24: M008231 | M24: 603PW | N24: Plasma | O24: 45974 | P24: 46028 | Q24: 0.52083333 | R24: 0.5625 | S24: =R24-Q24 -> 0.041666667 | T24: 2 | U24: =S24*T24 -> 0.083333333 | V24: PM | W24: CBM | X24: Water Leak Alarm 발생 | Y24: Circulation PFA Tube Line Tube 빠짐으로 Leak 발생 | Z24: 재조립 | AA24: - | AB24: 인건비 | AC24: - | AD24: - | AE24: 2 | AF24: 1년 | AG24: - | AH24: 무상 | AI24: - | AJ24: - | AK24: - | AL24: =IF(O24="","OUT",IF(TODAY()>O24+365,"OUT","IN")) -> IN | AM24: 46021 | AN24: =MONTH(P24) -> 1 | AO24: =P24-AM24 -> 7 | AQ24: 무상
A25: 33 | B25: 작업 | C25: CS4부 | D25: 원익머트리얼즈 | E25: - | F25: 종합사이트 | G25: - | H25: - | I25: - | J25: - | K25: - | L25: M008027 | M25: 1501HW | N25: H/W | O25: 45989 | P25: 46028 | Q25: 0.41666667 | R25: 0.75 | S25: =R25-Q25 -> 0.33333333 | T25: 2 | U25: =S25*T25 -> 0.66666667 | V25: PM | W25: CBM | X25: Circulation 및 Drain PVC 배관 열변형발생 | Y25: Wet Heater로 인한 Wet Temp 상승으로 PVC 배관 열변형 발생 | Z25: 내부 PM | AA25: - | AB25: 인건비 | AC25: - | AD25: - | AE25: 2 | AF25: 1년 | AG25: - | AH25: 무상 | AI25: - | AJ25: - | AK25: - | AL25: =IF(O25="","OUT",IF(TODAY()>O25+365,"OUT","IN")) -> IN | AM25: 46001 | AN25: =MONTH(P25) -> 1 | AO25: =P25-AM25 -> 27 | AQ25: 무상
A26: 34 | B26: 파트 | C26: CS4부 | D26: 원익머트리얼즈 | E26: - | F26: 종합사이트 | G26: - | H26: - | I26: - | J26: - | K26: - | L26: M008027 | M26: 1501HW | N26: H/W | O26: 45989 | P26: 46028 | Q26: 0.41666667 | R26: 0.75 | S26: =R26-Q26 -> 0.33333333 | T26: 2 | U26: =S26*T26 -> 0.66666667 | V26: PM | W26: CBM | X26: Circulation 및 Drain PVC 배관 열변형발생 | Y26: Wet Heater로 인한 Wet Temp 상승으로 PVC 배관 열변형 발생 | Z26: PVC배관 교체 | AA26: 파트 | AB26: CENTER-RING | AC26: 903-010-000-02 | AD26: - | AE26: 8 | AF26: 1년 | AG26: 39 | AH26: 유상 | AI26: - | AJ26: - | AK26: NW50-오링 포함 (STS304+Super Vtion) | AL26: =IF(O26="","OUT",IF(TODAY()>O26+365,"OUT","IN")) -> IN | AM26: 46001 | AN26: =MONTH(P26) -> 1 | AO26: =P26-AM26 -> 27 | AQ26: 유상
A27: 35 | B27: 파트 | C27: CS4부 | D27: 원익머트리얼즈 | E27: - | F27: 종합사이트 | G27: - | H27: - | I27: - | J27: - | K27: - | L27: M008027 | M27: 1501HW | N27: H/W | O27: 45989 | P27: 46028 | Q27: 0.41666667 | R27: 0.75 | S27: =R27-Q27 -> 0.33333333 | T27: 2 | U27: =S27*T27 -> 0.66666667 | V27: PM | W27: CBM | X27: Circulation 및 Drain PVC 배관 열변형발생 | Y27: Wet Heater로 인한 Wet Temp 상승으로 PVC 배관 열변형 발생 | Z27: PVC배관 교체 | AA27: 파트 | AB27: CENTER-RING | AC27: 903-010-005 | AD27: - | AE27: 1 | AF27: 1년 | AG27: 39 | AH27: 유상 | AK27: NW160-오링 포함 | AL27: =IF(O27="","OUT",IF(TODAY()>O27+365,"OUT","IN")) -> IN | AM27: 46001 | AN27: =MONTH(P27) -> 1 | AO27: =P27-AM27 -> 27 | AQ27: 유상
A28: 36 | B28: 파트 | C28: CS4부 | D28: 원익머트리얼즈 | E28: - | F28: 종합사이트 | G28: - | H28: - | I28: - | J28: - | K28: - | L28: M008027 | M28: 1501HW | N28: H/W | O28: 45989 | P28: 46028 | Q28: 0.41666667 | R28: 0.75 | S28: =R28-Q28 -> 0.33333333 | T28: 2 | U28: =S28*T28 -> 0.66666667 | V28: PM | W28: CBM | X28: Circulation 및 Drain PVC 배관 열변형발생 | Y28: Wet Heater로 인한 Wet Temp 상승으로 PVC 배관 열변형 발생 | Z28: PVC배관 교체 | AA28: 파트 | AB28: CENTER-RING | AC28: 903-010-008 | AD28: - | AE28: 1 | AF28: 1년 | AG28: 39 | AH28: 유상 | AK28: NW125-오링 포함 | AL28: =IF(O28="","OUT",IF(TODAY()>O28+365,"OUT","IN")) -> IN | AM28: 46001 | AN28: =MONTH(P28) -> 1 | AO28: =P28-AM28 -> 27 | AQ28: 유상
A29: 37 | B29: 파트 | C29: CS4부 | D29: 원익머트리얼즈 | E29: - | F29: 종합사이트 | G29: - | H29: - | I29: - | J29: - | K29: - | L29: M008027 | M29: 1501HW | N29: H/W | O29: 45989 | P29: 46028 | Q29: 0.41666667 | R29: 0.75 | S29: =R29-Q29 -> 0.33333333 | T29: 2 | U29: =S29*T29 -> 0.66666667 | V29: PM | W29: CBM | X29: Circulation 및 Drain PVC 배관 열변형발생 | Y29: Wet Heater로 인한 Wet Temp 상승으로 PVC 배관 열변형 발생 | Z29: PVC배관 교체 | AA29: 파트 | AB29: CENTER-RING | AC29: 903-010-009 | AD29: - | AE29: 1 | AF29: 1년 | AG29: 39 | AH29: 유상 | AK29: NW200-오링 포함 | AL29: =IF(O29="","OUT",IF(TODAY()>O29+365,"OUT","IN")) -> IN | AM29: 46001 | AN29: =MONTH(P29) -> 1 | AO29: =P29-AM29 -> 27 | AQ29: 유상
A30: 38 | B30: 파트 | C30: CS4부 | D30: 원익머트리얼즈 | E30: - | F30: 종합사이트 | G30: - | H30: - | I30: - | J30: - | K30: - | L30: M008027 | M30: 1501HW | N30: H/W | O30: 45989 | P30: 46028 | Q30: 0.41666667 | R30: 0.75 | S30: =R30-Q30 -> 0.33333333 | T30: 2 | U30: =S30*T30 -> 0.66666667 | V30: PM | W30: CBM | X30: Circulation 및 Drain PVC 배관 열변형발생 | Y30: Wet Heater로 인한 Wet Temp 상승으로 PVC 배관 열변형 발생 | Z30: PVC배관 교체 | AA30: 파트 | AB30: O-RING | AC30: 903-016-620-01 | AD30: - | AE30: 2 | AF30: 1년 | AG30: 39 | AH30: 유상 | AK30: P620 (SUPER VITON) | AL30: =IF(O30="","OUT",IF(TODAY()>O30+365,"OUT","IN")) -> IN | AM30: 46001 | AN30: =MONTH(P30) -> 1 | AO30: =P30-AM30 -> 27 | AQ30: 유상
A31: 39 | B31: 파트 | C31: CS4부 | D31: 원익머트리얼즈 | E31: - | F31: 종합사이트 | G31: - | H31: - | I31: - | J31: - | K31: - | L31: M008027 | M31: 1501HW | N31: H/W | O31: 45989 | P31: 46028 | Q31: 0.41666667 | R31: 0.75 | S31: =R31-Q31 -> 0.33333333 | T31: 2 | U31: =S31*T31 -> 0.66666667 | V31: PM | W31: CBM | X31: Circulation 및 Drain PVC 배관 열변형발생 | Y31: Wet Heater로 인한 Wet Temp 상승으로 PVC 배관 열변형 발생 | Z31: PVC배관 교체 | AA31: 파트 | AB31: O-RING | AC31: 903-017-035 | AD31: - | AE31: 1 | AF31: 1년 | AG31: 39 | AH31: 유상 | AK31: G35 | AL31: =IF(O31="","OUT",IF(TODAY()>O31+365,"OUT","IN")) -> IN | AM31: 46001 | AN31: =MONTH(P31) -> 1 | AO31: =P31-AM31 -> 27 | AQ31: 유상
A32: 40 | B32: 파트 | C32: CS4부 | D32: 원익머트리얼즈 | E32: - | F32: 종합사이트 | G32: - | H32: - | I32: - | J32: - | K32: - | L32: M008027 | M32: 1501HW | N32: H/W | O32: 45989 | P32: 46028 | Q32: 0.41666667 | R32: 0.75 | S32: =R32-Q32 -> 0.33333333 | T32: 2 | U32: =S32*T32 -> 0.66666667 | V32: PM | W32: CBM | X32: Circulation 및 Drain PVC 배관 열변형발생 | Y32: Wet Heater로 인한 Wet Temp 상승으로 PVC 배관 열변형 발생 | Z32: PVC배관 교체 | AA32: 파트 | AB32: O-RING | AC32: 903-017-070 | AD32: - | AE32: 2 | AF32: 1년 | AG32: 39 | AH32: 유상 | AK32: G70 | AL32: =IF(O32="","OUT",IF(TODAY()>O32+365,"OUT","IN")) -> IN | AM32: 46001 | AN32: =MONTH(P32) -> 1 | AO32: =P32-AM32 -> 27 | AQ32: 유상
A33: 41 | B33: 파트 | C33: CS4부 | D33: 원익머트리얼즈 | E33: - | F33: 종합사이트 | G33: - | H33: - | I33: - | J33: - | K33: - | L33: M008027 | M33: 1501HW | N33: H/W | O33: 45989 | P33: 46028 | Q33: 0.41666667 | R33: 0.75 | S33: =R33-Q33 -> 0.33333333 | T33: 2 | U33: =S33*T33 -> 0.66666667 | V33: PM | W33: CBM | X33: Circulation 및 Drain PVC 배관 열변형발생 | Y33: Wet Heater로 인한 Wet Temp 상승으로 PVC 배관 열변형 발생 | Z33: PVC배관 교체 | AA33: 파트 | AB33: CIR. 하단배관 | AC33: 1501-170-S21-01 | AD33: - | AE33: 1 | AF33: 1년 | AG33: 39 | AH33: 유상 | AK33: 1501-170-S21-01 | AL33: =IF(O33="","OUT",IF(TODAY()>O33+365,"OUT","IN")) -> IN | AM33: 46001 | AN33: =MONTH(P33) -> 1 | AO33: =P33-AM33 -> 27 | AQ33: 유상
A34: 42 | B34: 파트 | C34: CS4부 | D34: 원익머트리얼즈 | E34: - | F34: 종합사이트 | G34: - | H34: - | I34: - | J34: - | K34: - | L34: M008027 | M34: 1501HW | N34: H/W | O34: 45989 | P34: 46028 | Q34: 0.41666667 | R34: 0.75 | S34: =R34-Q34 -> 0.33333333 | T34: 2 | U34: =S34*T34 -> 0.66666667 | V34: PM | W34: CBM | X34: Circulation 및 Drain PVC 배관 열변형발생 | Y34: Wet Heater로 인한 Wet Temp 상승으로 PVC 배관 열변형 발생 | Z34: PVC배관 교체 | AA34: 파트 | AB34: CIR. 상단배관 | AC34: 1501-170-S22-05 | AD34: - | AE34: 1 | AF34: 1년 | AG34: 39 | AH34: 유상 | AK34: 1501-170-S22-05 | AL34: =IF(O34="","OUT",IF(TODAY()>O34+365,"OUT","IN")) -> IN | AM34: 46001 | AN34: =MONTH(P34) -> 1 | AO34: =P34-AM34 -> 27 | AQ34: 유상
A35: 43 | B35: 파트 | C35: CS4부 | D35: 원익머트리얼즈 | E35: - | F35: 종합사이트 | G35: - | H35: - | I35: - | J35: - | K35: - | L35: M008027 | M35: 1501HW | N35: H/W | O35: 45989 | P35: 46028 | Q35: 0.41666667 | R35: 0.75 | S35: =R35-Q35 -> 0.33333333 | T35: 2 | U35: =S35*T35 -> 0.66666667 | V35: PM | W35: CBM | X35: Circulation 및 Drain PVC 배관 열변형발생 | Y35: Wet Heater로 인한 Wet Temp 상승으로 PVC 배관 열변형 발생 | Z35: PVC배관 교체 | AA35: 파트 | AB35: DRAIN 하단배관 | AC35: 1501-170-S31-01 | AD35: - | AE35: 1 | AF35: 1년 | AG35: 39 | AH35: 유상 | AK35: 1501-170-S31-01 | AL35: =IF(O35="","OUT",IF(TODAY()>O35+365,"OUT","IN")) -> IN | AM35: 46001 | AN35: =MONTH(P35) -> 1 | AO35: =P35-AM35 -> 27 | AQ35: 유상
A36: 44 | B36: 파트 | C36: CS4부 | D36: 원익머트리얼즈 | E36: - | F36: 종합사이트 | G36: - | H36: - | I36: - | J36: - | K36: - | L36: M008027 | M36: 1501HW | N36: H/W | O36: 45989 | P36: 46028 | Q36: 0.41666667 | R36: 0.75 | S36: =R36-Q36 -> 0.33333333 | T36: 2 | U36: =S36*T36 -> 0.66666667 | V36: PM | W36: CBM | X36: Circulation 및 Drain PVC 배관 열변형발생 | Y36: Wet Heater로 인한 Wet Temp 상승으로 PVC 배관 열변형 발생 | Z36: PVC배관 교체 | AA36: 파트 | AB36: DRAIN 상단배관 (VALVE 용접용 포함) | AC36: 1501-170-S32-05-P | AD36: - | AE36: 1 | AF36: 1년 | AG36: 39 | AH36: 유상 | AK36: 전동V/V Hynix Type | AL36: =IF(O36="","OUT",IF(TODAY()>O36+365,"OUT","IN")) -> IN | AM36: 46001 | AN36: =MONTH(P36) -> 1 | AO36: =P36-AM36 -> 27 | AQ36: 유상
A37: 45 | B37: 파트 | C37: CS4부 | D37: 원익머트리얼즈 | E37: - | F37: 종합사이트 | G37: - | H37: - | I37: - | J37: - | K37: - | L37: M008027 | M37: 1501HW | N37: H/W | O37: 45989 | P37: 46028 | Q37: 0.41666667 | R37: 0.75 | S37: =R37-Q37 -> 0.33333333 | T37: 2 | U37: =S37*T37 -> 0.66666667 | V37: PM | W37: CBM | X37: Circulation 및 Drain PVC 배관 열변형발생 | Y37: Wet Heater로 인한 Wet Temp 상승으로 PVC 배관 열변형 발생 | Z37: PVC배관 교체 | AA37: 파트 | AB37: PLC ANALOG UNIT | AC37: 901-047-051 | AD37: - | AE37: 1 | AF37: 1년 | AG37: 39 | AH37: 유상 | AK37: CJ1W-MAD42 | AL37: =IF(O37="","OUT",IF(TODAY()>O37+365,"OUT","IN")) -> IN | AM37: 46001 | AN37: =MONTH(P37) -> 1 | AO37: =P37-AM37 -> 27 | AQ37: 유상
A38: 46 | B38: 작업 | C38: CS4부 | D38: 온세미컨덕터코리아 | E38: - | F38: 종합사이트 | G38: EPI | H38: - | I38: - | J38: 전설비 | K38: - | L38: 전설비 | M38: 전설비 | N38: H/W | O38: - | P38: 46038 | Q38: 0.39583333 | R38: 0.61805556 | S38: =R38-Q38 -> 0.22222222 | T38: 3 | U38: =S38*T38 -> 0.66666667 | V38: PM | W38: 개선 | X38: 전 설비 점검 및 가동 TEST | Y38: 전 설비 점검 및 가동 TEST | Z38: 설비 점검 | AA38: - | AB38: 인건비 | AC38: - | AD38: - | AE38: 4 | AF38: 1년 | AG38: - | AH38: 무상 | AI38: - | AJ38: - | AK38: - | AL38: =IF(O38="","OUT",IF(TODAY()>O38+365,"OUT","IN")) -> #VALUE! | AM38: 46034 | AN38: =MONTH(P38) -> 1 | AO38: =P38-AM38 -> 4 | AQ38: 무상
A39: 47 | B39: 작업 | C39: CS4부 | D39: DB하이텍 | E39: - | F39: 종합사이트 | G39: - | H39: - | I39: - | J39: - | K39: - | L39: - | M39: 507BW | N39: H/W | O39: - | P39: 46038 | Q39: 0.4375 | R39: 0.47916667 | S39: =R39-Q39 -> 0.041666667 | T39: 1 | U39: =S39*T39 -> 0.041666667 | V39: 기타 | W39: 파트 반입 | X39: 도면수정을 위해 반출했던 Part's 재반입 | Y39: 도면수정을 위해 반출했던 Part's 재반입 | Z39: Part's 반입 | AA39: - | AB39: 인건비 | AC39: - | AD39: - | AE39: 1 | AF39: - | AG39: - | AH39: 무상 | AI39: - | AJ39: - | AK39: - | AL39: =IF(O39="","OUT",IF(TODAY()>O39+365,"OUT","IN")) -> #VALUE! | AM39: 46001 | AN39: =MONTH(P39) -> 1 | AO39: =P39-AM39 -> 37 | AQ39: 무상
A40: 48 | B40: 작업 | C40: CS4부 | D40: 동우화인켐 | E40: - | F40: 종합사이트 | G40: 2공장 | H40: CVD | I40: CVD | J40: 전설비 | K40: - | L40: 전설비 | M40: 전설비 | N40: Plasma | O40: - | P40: 46037 | Q40: 0.39583333 | R40: 0.52083333 | S40: =R40-Q40 -> 0.125 | T40: 3 | U40: =S40*T40 -> 0.375 | V40: PM | W40: CBM | X40: Water Leak Alarm 발생 | Y40: Circulation pump Manifold PFA TUBE 탈착 발생 | Z40: 원형Teflon FITTING 교체 | AA40: - | AB40: 인건비 | AC40: - | AD40: - | AE40: 3 | AF40: - | AG40: - | AH40: 무상 | AI40: - | AJ40: - | AK40: - | AL40: =IF(O40="","OUT",IF(TODAY()>O40+365,"OUT","IN")) -> #VALUE! | AM40: 46021 | AN40: =MONTH(P40) -> 1 | AO40: =P40-AM40 -> 16 | AQ40: 무상
...

Sheet Alarm 및 사용Part 이력(미사용)
A1: ■ 2021년도 점검 및 Part 사용이력
A2: NO. | B2: 상호 | C2: MODEL | D2: S/N | E2: Set-Up 일자 | F2: WARRENTY Out 여부 | G2: 이전 PM일 | H2: PM(작업) 일자 | I2: 월 | J2: 경과일 | K2: 작업자1 | L2: 작업자2 | M2: 작업자3 | N2: 작업자4 | O2: 유형 (점검,PM,파트교체,원인분석) | P2: Alarm 명 (현상 / 주원인) | Q2: 사용 Part | R2: 규격 | S2: Part Code | T2: 수량 | U2: 단위 | V2: 유/무상/ (업체)재고
A3: 1 | B3: AND | C3: 507BWA | D3: M002622 | F3: =IF(E3="","OUT",IF(TODAY()>E3+365,"OUT","IN")) -> OUT | G3: 43862 | H3: 44228 | I3: =MONTH(H3) -> 2 | J3: - | K3: 강웅모 | L3: 조재현 | O3: 점검 및 파트교체 | P3: Heater Fail로 인한 Team#1 Low알람 | Q3: HEATER | R3: 507,1207용(KANTHAL)- | S3: 901-030-104 | T3: 4 | U3: ea | V3: 유상
A4: 2 | B4: 동우화인켐 | C4: 1207BWA | D4: M002643 | E4: - | F4: - | G4: - | H4: 44228 | I4: =MONTH(H4) -> 2 | J4: =H4-G4 -> #VALUE! | K4: 정동교 | L4: 강웅모 | M4: 조재현 | O4: 점검 및 파트교체 | P4: Water Leak | Q4: PRESSURE SWITCH | R4: 901.64.PRESCAL , 50mbar~250mbar | S4: 901-055-026 | T4: 1 | U4: ea | V4: 유상
A5: 3 | B5: 동우화인켐 | C5: 1207BWA | D5: M002643 | E5: - | F5: - | G5: - | H5: 44228 | I5: =MONTH(H5) -> 2 | J5: =H5-G5 -> #VALUE! | K5: 정동교 | L5: 강웅모 | M5: 조재현 | O5: 점검 및 파트교체 | P5: Water Leak | Q5: FLOW METER(WATER) | R5: Z-300 (7L) | S5: 904-001-048 | T5: 1 | U5: ea | V5: 유상
A6: 4 | B6: 동우화인켐 | C6: 1207BWA | D6: M002643 | E6: - | F6: - | G6: - | H6: 44228 | I6: =MONTH(H6) -> 2 | J6: =H6-G6 -> #VALUE! | K6: 정동교 | L6: 강웅모 | M6: 조재현 | O6: 점검 및 파트교체 | P6: Water Leak | Q6: 페럴 | R6: 3/8＂-(너트포함) | S6: 900-003-003 | T6: 1 | U6: ea | V6: 유상
A7: 5 | B7: 동우화인켐 | C7: 1207BWA | D7: M002643 | E7: - | F7: - | G7: - | H7: 44228 | I7: =MONTH(H7) -> 2 | J7: =H7-G7 -> #VALUE! | K7: 정동교 | L7: 강웅모 | M7: 조재현 | O7: 점검 및 파트교체 | P7: Water Leak | Q7: 페럴 21 | R7: 1/2＂(너트포함) | S7: 900-003-000 | T7: 5 | U7: ea | V7: 유상
A8: 6 | B8: 동우화인켐 | C8: 1207BWA | D8: M002643 | E8: - | F8: - | G8: - | H8: 44228 | I8: =MONTH(H8) -> 2 | J8: =H8-G8 -> #VALUE! | K8: 강웅모 | L8: 조재현 | O8: PM,파트교체 | P8: PM | Q8: 사각 O-Ring | R8: 519*519 | S8: 903-001-210 | T8: 2 | U8: ea | V8: 업체 재고
A9: 7 | B9: 동우화인켐 | C9: 1207BWA | D9: M002643 | E9: - | F9: - | G9: - | H9: 44228 | I9: =MONTH(H9) -> 2 | K9: 정민욱 | O9: 이온스크러버 Leak | P9: Water Leak | Q9: 업체 방문하여 원인파악 | R9: - | S9: - | T9: - | U9: - | V9: -
A10: 8 | B10: 동우화인켐 | C10: 1207BWA | D10: M002643 | E10: - | F10: - | G10: - | H10: 44228 | I10: =MONTH(H10) -> 2 | J10: =H10-G10 -> #VALUE! | K10: 정민욱 | L10: 유니온테크(양동수부장) | O10: 이온스크러버 파트교체 | P10: - | Q10: ball type check valve(유니온테크에서 수급) | R10: - | S10: - | T10: 1 | U10: ea | V10: -
A11: 9 | B11: 동우화인켐 | C11: 1207BWA | D11: M002643 | E11: - | F11: - | G11: - | H11: 44228 | I11: =MONTH(H11) -> 2 | J11: =H11-G11 -> #VALUE! | K11: 정민욱 | O11: 파트교체 | P11: 열교환기 pump 공회전으로 인한 fail | Q11: 자흡식 pump | R11: NH-250PS-SP(자흡식) | S11: 901-048-014 | T11: 1 | U11: ea | V11: 유상
A12: 10 | B12: 동우화인켐 | C12: 1207BWA | D12: M002643 | E12: - | F12: - | G12: - | H12: 44228 | I12: =MONTH(H12) -> 2 | J12: =H12-G12 -> #VALUE! | K12: 정민욱 | O12: Trouble 점검 | P12: 이온스크러버 leak 로 인한 pump 침수로 main 전원 트립 | Q12: - | R12: - | S12: - | T12: - | U12: - | V12: 무상
A13: 11 | B13: 동우화인켐 | C13: 1207BWA | D13: M002643 | E13: - | F13: - | G13: - | H13: 44228 | I13: =MONTH(H13) -> 2 | J13: =H13-G13 -> #VALUE! | K13: 정민욱 | O13: Trouble 점검 | P13: 이온스크러버 leak 로 인한 pump 침수로 main 전원 트립 | Q13: - | R13: - | S13: - | T13: - | U13: - | V13: 무상
A14: 12 | B14: 미래보 | C14: 507BWS | D14: M005055 | E14: - | F14: OUT | G14: - | H14: 44279 | I14: =MONTH(H14) -> 3 | J14: =H14-G14 -> #VALUE! | K14: 강웅모 | L14: 조재현 | O14: PM,파트교체 | P14: Exh.Tower 부식(파우더 고착,코팅뜸현상) | Q14: EXH. MIDDLE | R14: 일체형 | S14: 1207A-160-S02-30 | T14: 1 | U14: ea | V14: 업체 재고
A15: 13 | B15: KIST | C15: MAT501 | D15: 20031013-KI-458 | F15: =IF(E15="","OUT",IF(TODAY()>E15+365,"OUT","IN")) -> OUT | G15: 43101 | H15: 44284 | I15: =MONTH(H15) -> 3 | J15: =H15-G15 -> 1183 | K15: 강웅모 | L15: 조재현 | O15: PM,파트교체 | P15: Exh연결단 Center-Ring 부식 | Q15: Center-Ring | R15: NW100 | S15: 903-010-003 | T15: 2 | U15: ea | V15: 업체 재고
A16: 14 | B16: 온세미컨덕터코리아 | C16: 1501HW | D16: M004953 | E16: 43560 | F16: =IF(E16="","OUT",IF(TODAY()>E16+365,"OUT","IN")) -> OUT | G16: 44271 | H16: 44285 | I16: =MONTH(H16) -> 3 | J16: =H16-G16 -> 14 | K16: 강웅모 | L16: 조재현 | O16: PM,파트교체 | P16: ABSORBER 부식 | Q16: Absorber | R16: 1＂-폴링(STS) | S16: 905-009-001-01 | T16: 6 | U16: kg | V16: 업체 재고
A17: 15 | B17: 한국알박 | C17: 이온스크러버 | D17: No Serial | F17: =IF(E17="","OUT",IF(TODAY()>E17+365,"OUT","IN")) -> OUT | G17: 44260 | H17: 44286 | I17: =MONTH(H17) -> 3 | J17: =H17-G17 -> 26 | K17: 강웅모 | L17: 조재현 | O17: PM,파트교체 | P17: ABS.Body 부식 | Q17: ABS. KIT BODY | R17: 플레이트분리형 | S17: M400-130-S02-00 | T17: 1 | U17: ea | V17: 업체 재고
A18: 16 | B18: 아데카코리아 | C18: 601WPW | D18: M004988 | E18: 43616 | F18: =IF(E18="","OUT",IF(TODAY()>E18+365,"OUT","IN")) -> OUT | G18: 44265 | H18: 44288 | I18: =MONTH(H18) -> 4 | J18: =H18-G18 -> 23 | K18: 강웅모 | L18: 조재현 | O18: PM,파트교체 | P18: ABS.Plate 부식 | Q18: ABS. KIT PLATE | R18: 1207-NEW | S18: 1207-130-S01-20 | T18: 1 | U18: ea | V18: 업체 재고
A19: 17 | B19: 아데카코리아 | C19: 601WPW | D19: M004988 | E19: 43616 | F19: =IF(E19="","OUT",IF(TODAY()>E19+365,"OUT","IN")) -> OUT | G19: 44265 | H19: 44288 | I19: =MONTH(H19) -> 4 | J19: =H19-G19 -> 23 | K19: 강웅모 | L19: 조재현 | O19: PM,파트교체 | P19: ABS.Plate 부식 | Q19: Punching Plate | R19: 480X239.5X5T | S19: M400-130-007-02 | T19: 1 | U19: ea | V19: 업체 재고
A20: 18 | B20: 한국알박 | C20: 이온스크러버 | D20: No Serial | E20: - | F20: OUT | G20: 44286 | H20: 44288 | I20: =MONTH(H20) -> 4 | J20: =H20-G20 -> 2 | K20: 강웅모 | L20: 조재현 | O20: PM,파트교체 | P20: 부식으로 인한 Hall발생 | Q20: Wet Chamber | R20: SMD 개선 | S20: 1207A-140-A30-02 | T20: 1 | U20: ea | V20: 업체 재고
A21: 19 | B21: 온세미컨덕터코리아 | C21: 1501HW | D21: M004952 | E21: 43560 | F21: OUT | G21: 44285 | H21: 44291 | I21: =MONTH(H21) -> 4 | J21: =H21-G21 -> 6 | K21: 강웅모 | L21: 조재현 | M21: 정민욱 | O21: 파트교체 | P21: Pump 임펠라 불량(크렉) | Q21: Pump 임팰러 Assy | R21: PM250용(motor부제외) | S21: 901-048-090 | T21: 1 | U21: ea | V21: 무상
A22: 20 | B22: 온세미컨덕터코리아 | C22: 1501HW | D22: M004952 | E22: 43560 | F22: OUT | G22: 44285 | H22: 44291 | I22: =MONTH(H22) -> 4 | J22: =H22-G22 -> 6 | K22: 강웅모 | L22: 조재현 | O22: PM,파트교체 | P22: PM | Q22: 사각 O-Ring | R22: 519*519 | S22: 903-001-210 | T22: 2 | U22: ea | V22: 업체 재고
A23: 21 | B23: 이루자 | C23: Mi2500BW | D23: M004920 | F23: OUT | H23: 44293 | I23: =MONTH(H23) -> 4 | J23: =H23-G23 -> 44293 | K23: 강웅모 | L23: 조재현 | O23: PM,파트교체 | P23: PM | Q23: 사각 O-Ring | R23: 519*519 | S23: 903-001-210 | T23: 2 | U23: ea | V23: 업체 재고
A24: 22 | B24: 한국알박 | C24: 이온스크러버 | D24: No Serial | E24: - | F24: OUT | G24: 44288 | H24: 44293 | I24: =MONTH(H24) -> 4 | J24: =H24-G24 -> 5 | K24: 윤태중 | L24: 정동교 | M24: 강웅모 | N24: 조재현 | O24: Trouble 점검 | P24: 천장에서 물이 떨어져 스크러버 전원 내려감 | Q24: DC Power Supply | R24: NDR-75-24 | S24: 901-022-006-01 | T24: 1 | U24: ea | V24: 유상
A25: 23 | B25: 동우화인켐 | C25: 1207BWA | D25: M003199 | E25: - | F25: OUT | G25: - | H25: 44294 | I25: =MONTH(H25) -> 4 | J25: =H25-G25 -> #VALUE! | K25: 강웅모 | L25: 조재현 | O25: PM,파트교체 | P25: 부식으로 인한 교체 | Q25: EXH. BOTTOM | S25: 1207A-160-S03-30 | T25: 1 | U25: ea | V25: 업체 재고
A26: 24 | B26: 동우화인켐 | C26: 1208BWA | D26: M003199 | E26: - | F26: OUT | G26: - | H26: 44294 | I26: =MONTH(H26) -> 4 | J26: =H26-G26 -> #VALUE! | K26: 강웅모 | L26: 조재현 | O26: PM,파트교체 | P26: Exh연결단 Center-Ring 부식 | Q26: Center-Ring | R26: NW100 | S26: 903-010-003 | T26: 1 | U26: ea | V26: 업체 재고
A27: 25 | B27: 동우화인켐 | C27: 1208BWA | D27: M003199 | E27: - | F27: OUT | G27: - | H27: 44294 | I27: =MONTH(H27) -> 4 | J27: =H27-G27 -> #VALUE! | K27: 강웅모 | L27: 조재현 | O27: Trouble 점검 | P27: Inlet Pressure High, Level High | Q27: - | R27: - | S27: - | T27: - | U27: - | V27: -
A28: 26 | B28: 동우화인켐 | C28: 1208BWA | D28: M003199 | E28: - | F28: OUT | G28: - | H28: 44294 | I28: =MONTH(H28) -> 4 | J28: =H28-G28 -> #VALUE! | K28: 윤태중 | L28: 정동교 | M28: 강웅모 | N28: 조재현 | O28: Trouble 점검 | P28: 천장에서 물이 떨어져 스크러버 전원 내려감 | Q28: Inverter | R28: SV008iC5-1 | S28: 901-200-000 | T28: 1 | U28: ea | V28: 유상
A29: 27 | B29: 동우화인켐 | C29: 1207BWA | D29: M003200 | E29: - | F29: - | G29: - | H29: 44299 | I29: =MONTH(H29) -> 4 | J29: =H29-G29 -> #VALUE! | K29: 강웅모 | L29: 조재현 | O29: PM,파트교체 | P29: ABSORBER 부식 | Q29: Absorber | R29: 1＂-폴링(STS) | S29: 905-009-001-01 | T29: 6 | U29: kg | V29: 업체 재고
A30: 28 | B30: 동우화인켐 | C30: 1207BWA | D30: M003200 | E30: - | F30: - | G30: - | H30: 44299 | I30: =MONTH(H30) -> 4 | J30: =H30-G30 -> #VALUE! | K30: 강웅모 | L30: 조재현 | O30: PM,파트교체 | P30: Leak발생으로 인한 교체 | Q30: U-TRAP DRAIN | R30: 1207BWA | S30: 1207A-170-S51-01 | T30: 1 | U30: ea | V30: 업체 재고
A31: 29 | B31: 테스(용인) | C31: 1207BWA | D31: M003290 | E31: - | F31: OUT | G31: - | H31: 44299 | I31: =MONTH(H31) -> 4 | J31: =H31-G31 -> #VALUE! | K31: 강웅모 | L31: 조재현 | O31: PM,파트교체 | P31: 부식으로 인한 교체 | Q31: Wet Chamber | R31: SMD 개선 | S31: 1207A-140-A30-02 | T31: 1 | U31: ea | V31: 업체 재고
A32: 30 | B32: 테스(용인) | C32: 1207BWA | D32: M003290 | E32: - | F32: OUT | G32: - | H32: 44299 | I32: =MONTH(H32) -> 4 | J32: =H32-G32 -> #VALUE! | K32: 강웅모 | L32: 조재현 | O32: PM,파트교체 | P32: PM | Q32: 사각 O-Ring | R32: 519*519 | S32: 903-001-210 | T32: 2 | U32: ea | V32: 업체 재고
A33: 31 | B33: 비아트론 | C33: Mi2000BW | D33: M005536 | E33: 44302 | F33: IN | H33: 44302 | I33: =MONTH(H33) -> 4 | J33: =H33-G33 -> 44302 | K33: 강웅모 | L33: 조재현 | O33: PM,파트교체 | P33: ABS.Plate 부식 | Q33: Punching Plate | R33: 480X239.5X5T | S33: M400-130-007-02 | T33: 1 | U33: ea | V33: 업체 재고
A34: 32 | B34: 온세미컨덕터코리아 | C34: 1501HW | D34: M004952 | E34: 43560 | F34: OUT | G34: 44291 | H34: 44305 | I34: =MONTH(H34) -> 4 | J34: =H34-G34 -> 14 | K34: 강웅모 | L34: 조재현 | O34: PM,파트교체 | P34: ABS.Plate 부식 | Q34: ABS. KIT PLATE | R34: 1207-NEW | S34: 1207-130-S01-20 | T34: 1 | U34: ea | V34: 업체 재고
A35: 33 | B35: 동우화인켐 | C35: 1207BWA | D35: M003193 | E35: - | F35: - | G35: - | H35: 44306 | I35: =MONTH(H35) -> 4 | J35: =H35-G35 -> #VALUE! | K35: 정동교 | L35: 강웅모 | M35: 조재현 | O35: PM,파트교체 | P35: 담당자 요청 Heat Chamber Swap 교체 | Q35: - | R35: - | S35: - | T35: - | U35: - | V35: -
A36: 34 | B36: 동우화인켐 | C36: 1207BWA | D36: M003193 | E36: - | F36: - | G36: - | H36: 44306 | I36: =MONTH(H36) -> 4 | J36: =H36-G36 -> #VALUE! | K36: 강웅모 | L36: 조재현 | O36: 파트교체 | P36: 부식으로인한 파트교체 | Q36: PVC UNION BALL VALVE | R36: 20A | S36: 908-010-001 | T36: 1 | U36: ea | V36: 유상
A37: 35 | B37: 동우화인켐 | C37: 1207BWA | D37: M003193 | E37: - | F37: - | G37: - | H37: 44306 | I37: =MONTH(H37) -> 4 | J37: =H37-G37 -> #VALUE! | K37: 강웅모 | L37: 조재현 | O37: 파트교체 | P37: 부식으로인한 파트교체 | Q37: PVC UNION BALL VALVE | R37: 30A | S37: 908-010-003 | T37: 4 | U37: ea | V37: 유상
A38: 36 | B38: 동우화인켐 | C38: 1207BWA | D38: M003193 | E38: - | F38: - | G38: - | H38: 44306 | I38: =MONTH(H38) -> 4 | J38: =H38-G38 -> #VALUE! | K38: 정동교 | O38: 파트교체 | P38: ELCB TRIP / Housing변형으로 Heat Chamber Swap | Q38: - | R38: - | S38: - | T38: - | U38: - | V38: -
A39: 37 | B39: 동우화인켐 | C39: 1207BWA | D39: M003193 | E39: - | F39: - | G39: - | H39: 44306 | I39: =MONTH(H39) -> 4 | J39: =H39-G39 -> #VALUE! | K39: 강웅모 | L39: 조재현 | O39: PM,파트교체 | P39: 부식으로 인한 Bellows 파손 | Q39: INLET FLEXIBLE | R39: Ø75x210L | S39: BL-KF50L210-01 | T39: 1 | U39: ea | V39: 업체 재고
A40: 38 | B40: 동우화인켐 | C40: 1207BWA | D40: M003193 | E40: - | F40: - | G40: - | H40: 44306 | I40: =MONTH(H40) -> 4 | J40: =H40-G40 -> #VALUE! | K40: 강웅모 | L40: 조재현 | O40: PM,파트교체 | P40: 부식으로 인한 교체 | Q40: Center-Ring | R40: NW50 | S40: 903-010-000 | T40: 1 | U40: ea | V40: 업체 재고
...

Sheet 1.AND
B2: 1 | C2: AND
B7: 날짜 | C7: 납기 (없으면 안써도됨) | D7: 담당자 | E7: Model | F7: S/N | G7: 특이사항 (준비사항) | O7: 구분
B8: 44972 | G8: 설비 파워마스터에 판매 한 것으로 추정 | O8: 숙지사항

Sheet 2.AP System
B2: 2 | C2: AP System
B7: 날짜 | C7: 납기 (없으면 안써도됨) | D7: 담당자 | E7: Model | F7: S/N | G7: 특이사항 (준비사항) | O7: 구분

Sheet 4,JNK
B2: 4 | C2: JNK
B7: 날짜 | C7: 납기 (없으면 안써도됨) | D7: 담당자 | E7: Model | F7: S/N | G7: 특이사항 (준비사항) | O7: 구분

Sheet 3.BJ Power
B2: 3 | C2: BJ Power
B7: 날짜 | C7: 납기 (없으면 안써도됨) | D7: 담당자 | E7: Model | F7: S/N | G7: 특이사항 (준비사항) | O7: 구분

Sheet 5.Kanc
A1: 0
B2: 5 | C2: Kanc
B7: 날짜 | C7: 납기 (없으면 안써도됨) | D7: 담당자 | E7: Model | F7: S/N | G7: 특이사항 (준비사항) | O7: 구분

Sheet 6.KEC
B2: 6 | C2: KEC
B7: 날짜 | C7: 납기 (없으면 안써도됨) | D7: 담당자 | E7: Model (없으면 안써도됨) | F7: S/N (없으면 안써도됨) | G7: 특이사항 (준비사항) | O7: 구분
B8: 44539 | D8: 임영만 | E8: 507BWS | G8: Burn Chamber 교체 (SIC Heater -> Khantal Heater로 Type 변경) 50바이톤 4개 추가로 챙겨감 남으면 다시 이계환 부장님께 갖다줘야됨 | O8: 완료
B9: 44540 | C9: 다음 방문시 까지 | D9: 임영만 | E9: 507BWS | F9: 20050331-KE-1159 | G9: - In-Let Bellows 길이 짧아서 기존 짧은거 2개 이어서 설치함. 다음 방문시 50A 180mm~200mm Bellows챙겨가야함 (강차장님이 유상으로 하라고함) - Chamber 지지대 Bolt Nut Fail로 지지대 달지 못함 (설비 상부에 있음) 다음 방문시 Bolt Nut 챙겨서 설치 해야함 (M8 렌치볼트 추정 확인필요) - Cleaning Air Sol Valve 빼놓음 (이제 안씀), 3/8 Plug 없어서 막아놓지 못하고 튜브 꺾어서 케이블타이 처리 해놓음 | O9: 미완료
B10: 44557 | D10: 임영만 | E10: 507BWS | F10: 확인필요 | G10: 고객사가 설비 PM 후 압력 및 레벨 문제 발생하여 방문요청 했다고 함. 강차장님은 DC Power Supply 문제 추정하신다고 함. | O10: 완료
B11: 44565 | D11: 임영만 | E11: 507BWS | G11: 12/10 PM설비 In-Let Bellows 1개랑, Overhaul 장비 In-Let Bellows 2개 총3개 작업의뢰서 발주 완료 (유상으로 진행, 강차장님이 임영만기사랑 통화완료) | O11: 완료
B12: 44586 | G12: Pressure 관련 방문인원 내용 기입하세요 | O12: 미완료
B13: 44587 | D13: 임영만 | E13: 507BWS | G13: In-Let Bellows 3개 中 1개는 일전에 작업했던 20050331-KE-1159 설비에 짧은거 2개 연결 해놓았던 것에 사용함. 2개는 Overhaul 설비에 사용 예정 | O13: 완료
